Workbook

Sheet Data Entry Sheet
AS1: VRIN | AU1: TRIN | AW1: DRIN | AY1: RV | BA1: DEV | BC1: II | BE1: NT | BG1: MIS | BI1: MAN | BK1: AGG | BM1: SH | BO1: LOSE | BQ1: SUPR | BS1: EP | BU1: DEP | BW1: PT | BY1: EXH | CA1: ENT | CC1: DET | CE1: DIS | CG1: IMP | CI1: PRP | CK1: WRK | CM1: ParPD | CQ1: SzdPR | CU1: StpPD | CY1: ASPD | DC1: BPD | DG1: HPD | DK1: NPD | DO1: AvPD | DS1: DpnPD | DW1: OCPD | EA1: DprPD | EE1: PAPD
B2: SNAP-390 Scoring Program (© 2014 Lee Anna Clark & Leonard J. Simms) | AE2: Name | AF2: Number | AG2: Date | AH2: Clinician | AI2: items 1-60 | AJ2: items 61-120 | AK2: items 121-180 | AL2: items 181-240 | AM2: items 241-300 | AN2: items 301-360 | AO2: items 361-390 | AP2: Char err | AQ2: Length err | AR2: Omits | AS2: Raw | AT2: T | AU2: Raw | AV2: T | AW2: Raw | AX2: T | AY2: Raw | AZ2: T | BA2: Raw | BB2: T | BC2: Raw | BD2: T | BE2: Raw | BF2: T | BG2: Raw | BH2: T | BI2: Raw | BJ2: T | BK2: Raw | BL2: T | BM2: Raw | BN2: T | BO2: Raw | BP2: T | BQ2: Raw | BR2: T | BS2: Raw | BT2: T | BU2: Raw | BV2: T | BW2: Raw | BX2: T | BY2: Raw | BZ2: T | CA2: Raw | CB2: T | CC2: Raw | CD2: T | CE2: Raw | CF2: T | CG2: Raw | CH2: T | CI2: Raw | CJ2: T | CK2: Raw | CL2: T | CM2: Raw | CN2: T | CO2: Crit# | CP2: Dx? | CQ2: Raw | CR2: T | CS2: Crit# | CT2: Dx? | CU2: Raw | CV2: T | CW2: Crit# | CX2: Dx? | CY2: Raw | CZ2: T | DA2: Crit# | DB2: Dx? | DC2: Raw | DD2: T | DE2: Crit# | DF2: Dx? | DG2: Raw | DH2: T | DI2: Crit# | DJ2: Dx? | DK2: Raw | DL2: T | DM2: Crit# | DN2: Dx? | DO2: Raw | DP2: T | DQ2: Crit# | DR2: Dx? | DS2: Raw | DT2: T | DU2: Crit# | DV2: Dx? | DW2: Raw | DX2: T | DY2: Crit# | DZ2: Dx? | EA2: Raw | EB2: T | EC2: Crit# | ED2: Dx? | EE2: Raw | EF2: T | EG2: Crit# | EH2: Dx?
B3: v1.1 (July 2003): Scores the 390-item version of SNAP | AE3: =C5 -> Alex Carter | AF3: =C6 | AG3: =C7 | AH3: =C8 | AI3: =C11 -> 222121222122222221222222111211222221122222222222222212122212 | AJ3: =C12 -> 112122222222211211212211222212221121222222222222222222222222 | AK3: =C13 -> 222122222212121222122222212111211211222222211211222221121111 | AL3: =C14 -> 112121222212222221111122212222222222222222222222222222222221 | AM3: =C15 -> 212222221212112112222211222222222222222222212222222222122221 | AN3: =C16 -> 222221212221212212122211212121122222211221212222222222222222 | AO3: =C17 -> 221222222222222222222222222222 | AP3: =C20 -> 0 | AQ3: =C21 -> 0 | AR3: =C22 -> 0 | AS3: =V10 -> 9 | AT3: =W10 -> 67 | AU3: =V11 -> 11 | AV3: =W11 -> 26 | AW3: =V12 -> 17 | AX3: =W12 -> 40 | AY3: =V13 -> 3 | AZ3: =W13 -> 50 | BA3: =V14 -> 7 | BB3: =W14 -> 71 | BC3: =V16 -> 28 | BD3: =W16 -> 74 | BE3: =V19 -> 3 | BF3: =W19 -> 40 | BG3: =V20 -> 4 | BH3: =W20 -> 49 | BI3: =V21 -> 3 | BJ3: =W21 -> 47 | BK3: =V22 -> 6 | BL3: =W22 -> 58 | BM3: =V23 -> 6 | BN3: =W23 -> 66 | BO3: =V24 -> 3 | BP3: =W24 -> 65 | BQ3: =V25 -> 3 | BR3: =W25 -> 63 | BS3: =V26 -> 2 | BT3: =W26 -> 44 | BU3: =V27 -> 5 | BV3: =W27 -> 53 | BW3: =V29 -> 13 | BX3: =W29 -> 40 | BY3: =V30 -> 6 | BZ3: =W30 -> 48 | CA3: =V31 -> 5 | CB3: =W31 -> 41 | CC3: =V32 -> 5 | CD3: =W32 -> 49 | CE3: =V34 -> 10 | CF3: =W34 -> 52 | CG3: =V35 -> 9 | CH3: =W35 -> 59 | CI3: =V36 -> 8 | CJ3: =W36 -> 42 | CK3: =V37 -> 6 | CL3: =W37 -> 46 | CM3: =Z23 -> 4 | CN3: =AA23 -> 46 | CO3: =AB23 -> 0 | CP3: =AC23 -> N | CQ3: =Z24 -> 7 | CR3: =AA24 -> 55 | CS3: =AB24 -> 0 | CT3: =AC24 -> N | CU3: =Z25 -> 5 | CV3: =AA25 -> 46 | CW3: =AB25 -> 0 | CX3: =AC25 -> N | CY3: =Z27 -> 6 | CZ3: =AA27 -> 48 | DA3: =AB27 -> 0/2 | DB3: =AC27 -> N | DC3: =Z28 -> 8 | DD3: =AA28 -> 53 | DE3: =AB28 -> 0 | DF3: =AC28 -> N | DG3: =Z29 -> 5 | DH3: =AA29 -> 41 | DI3: =AB29 -> 0 | DJ3: =AC29 -> N | DK3: =Z30 -> 6 | DL3: =AA30 -> 41 | DM3: =AB30 -> 0 | DN3: =AC30 -> N | DO3: =Z32 -> 3 | DP3: =AA32 -> 44 | DQ3: =AB32 -> 0 | DR3: =AC32 -> N | DS3: =Z33 -> 2 | DT3: =AA33 -> 47 | DU3: =AB33 -> 0 | DV3: =AC33 -> N | DW3: =Z34 -> 8 | DX3: =AA34 -> 41 | DY3: =AB34 -> 1 | DZ3: =AC34 -> N | EA3: =Z36 -> 3 | EB3: =AA36 -> 42 | EC3: =AB36 -> 0 | ED3: =AC36 -> N | EE3: =Z37 -> 3 | EF3: =AA37 -> 46 | EG3: =AB37 -> 0 | EH3: =AC37 -> N
B5: Client name: | C5: Alex Carter | U5: SNAP Scoring Summary (v1.1) | AI5: Dx Scales
B6: Clinic number: | V6: Scores | AE6: Item | AF6: Resp | AG6: FK? | AH6: Keyed | AI6: TK | AJ6: FK | AL6: NT | AO6: MIS | AR6: MAN | AU6: AGG | AX6: SH | BA6: LOW SE | BD6: SUI PR | BG6: ECC PERC | BJ6: DEPEN | BM6: PT | BP6: EXHIB | BS6: ENTITL | BV6: DETACH | BY6: IMPUL | CB6: PROP | CE6: WORK | CH6: RV | CK6: DEV | CP6: DIS | CU6: ANTISOCIAL | CZ6: AVOIDANT | DE6: BORDERLINE | DJ6: DEPENDENT | DO6: DEPRESSIVE | DT6: HISTRIONIC | DY6: NARCISSISTIC | ED6: PAG/NEG | EI6: OCPD | EN6: PARANOID | ES6: SCHIZOID | EX6: SCHIZOTYPAL | FC6: VRIN | FI6: TRIN | FO6: DRIN | FX6: BDEV
B7: Date of testing: | V7: Raw | W7: T | AE7: 1 | AF7: =IF(ISERROR(VALUE(MID($C$11,$AE7,1)))=TRUE,"TEXT",VALUE(MID($C$11,$AE7,1))) -> 2 | AH7: =IF(AF7=9,0,(IF(AG7="Y",AF7-1,2-AF7))) -> 0 | AI7: =IF(AF7=1,1,0) -> 0 | AJ7: =IF(AF7=2,1,0) -> 1 | AL7: item | AM7: response | AO7: item | AP7: response | AR7: item | AS7: response | AU7: item | AV7: response | AX7: item | AY7: response | BA7: item | BB7: response | BD7: item | BE7: response | BG7: item | BH7: response | BJ7: item | BK7: response | BM7: item | BN7: response | BP7: item | BQ7: response | BS7: item | BT7: response | BV7: item | BW7: response | BY7: item | BZ7: response | CB7: item | CC7: response | CE7: item | CF7: response | CH7: item | CI7: response | CK7: item-t | CL7: resp | CM7: item-f | CN7: resp | CP7: item-t | CQ7: resp | CR7: item-f | CS7: resp | CU7: item-t | CV7: resp | CW7: item-f | CX7: resp | CZ7: item-t | DA7: resp | DB7: item-f | DC7: resp | DE7: item-t | DF7: resp | DG7: item-f | DH7: resp | DJ7: item-t | DK7: resp | DL7: item-f | DM7: resp | DO7: item-t | DP7: resp | DQ7: item-f | DR7: resp | DT7: item-t | DU7: resp | DV7: item-f | DW7: resp | DY7: item-t | DZ7: resp | EA7: item-f | EB7: resp | ED7: item-t | EE7: resp | EF7: item-f | EG7: resp | EI7: item-t | EJ7: resp | EK7: item-f | EL7: resp | EN7: item-t | EO7: resp | EP7: item-f | EQ7: resp | ES7: item-t | ET7: resp | EU7: item-f | EV7: resp | EX7: item-t | EY7: resp | EZ7: item-f | FA7: resp | FC7: item-1 | FD7: resp | FE7: item-2 | FF7: resp | FG7: inc | FI7: item-t | FJ7: resp | FO7: item-hi | FP7: resp | FQ7: FK? | FR7: kresp | FS7: item-lo | FT7: resp | FU7: FK? | FV7: kresp | FX7: item-t | FY7: resp | FZ7: item-f | GA7: resp
B8: Clinician: | Y8: Client name: | Z8: =C5 -> Alex Carter | AE8: 2 | AF8: =IF(ISERROR(VALUE(MID($C$11,$AE8,1)))=TRUE,"TEXT",VALUE(MID($C$11,$AE8,1))) -> 2 | AH8: =IF(AF8=9,0,(IF(AG8="Y",AF8-1,2-AF8))) -> 0 | AI8: =IF(AF8=1,1,0) -> 0 | AJ8: =IF(AF8=2,1,0) -> 1 | AL8: 241 | AM8: =VLOOKUP(AL8,$AE$7:$AH$396,4) -> 0 | AO8: 8 | AP8: =VLOOKUP(AO8,$AE$7:$AH$396,4) -> 0 | AR8: 12 | AS8: =VLOOKUP(AR8,$AE$7:$AH$396,4) -> 0 | AU8: 2 | AV8: =VLOOKUP(AU8,$AE$7:$AH$396,4) -> 0 | AX8: 13 | AY8: =VLOOKUP(AX8,$AE$7:$AH$396,4) -> 0 | BA8: 13 | BB8: =VLOOKUP(BA8,$AE$7:$AH$396,4) -> 0 | BD8: 30 | BE8: =VLOOKUP(BD8,$AE$7:$AH$396,4) -> 1 | BG8: 7 | BH8: =VLOOKUP(BG8,$AE$7:$AH$396,4) -> 0 | BJ8: 16 | BK8: =VLOOKUP(BJ8,$AE$7:$AH$396,4) -> 1 | BM8: 211 | BN8: =VLOOKUP(BM8,$AE$7:$AH$396,4) -> 0 | BP8: 6 | BQ8: =VLOOKUP(BP8,$AE$7:$AH$396,4) -> 0 | BS8: 49 | BT8: =VLOOKUP(BS8,$AE$7:$AH$396,4) -> 0 | BV8: 9 | BW8: =VLOOKUP(BV8,$AE$7:$AH$396,4) -> 0 | BY8: 4 | BZ8: =VLOOKUP(BY8,$AE$7:$AH$396,4) -> 0 | CB8: 3 | CC8: =VLOOKUP(CB8,$AE$7:$AH$396,4) -> 0 | CE8: 1 | CF8: =VLOOKUP(CE8,$AE$7:$AH$396,4) -> 0 | CH8: 255 | CI8: =VLOOKUP(CH8,$AE$7:$AH$396,4) -> 0 | CK8: 22 | CL8: =VLOOKUP(CK8,$AE$7:$AJ$396,5) -> 0 | CM8: 3 | CN8: =VLOOKUP(CM8,$AE$7:$AJ$396,6) -> 1 | CP8: 33 | CQ8: =VLOOKUP(CP8,$AE$7:$AJ$396,5) -> 0 | CR8: 4 | CS8: =VLOOKUP(CR8,$AE$7:$AJ$396,6) -> 0 | CU8: 5 | CV8: =VLOOKUP(CU8,$AE$7:$AJ$396,5) -> 0 | CW8: 29 | CX8: =VLOOKUP(CW8,$AE$7:$AJ$396,6) -> 0 | CZ8: 6 | DA8: =VLOOKUP(CZ8,$AE$7:$AJ$396,5) -> 1 | DB8: 74 | DC8: =VLOOKUP(DB8,$AE$7:$AJ$396,6) -> 0 | DE8: 11 | DF8: =VLOOKUP(DE8,$AE$7:$AJ$396,5) -> 0 | DG8: 37 | DH8: =VLOOKUP(DG8,$AE$7:$AJ$396,6) -> 0 | DJ8: 40 | DK8: =VLOOKUP(DJ8,$AE$7:$AJ$396,5) -> 0 | DL8: 16 | DM8: =VLOOKUP(DL8,$AE$7:$AJ$396,6) -> 1 | DO8: 13 | DP8: =VLOOKUP(DO8,$AE$7:$AJ$396,5) -> 0 | DQ8: 161 | DR8: =VLOOKUP(DQ8,$AE$7:$AJ$396,6) -> 1 | DT8: 57 | DU8: =VLOOKUP(DT8,$AE$7:$AJ$396,5) -> 0 | DV8: 19 | DW8: =VLOOKUP(DV8,$AE$7:$AJ$396,6) -> 1 | DY8: 49 | DZ8: =VLOOKUP(DY8,$AE$7:$AJ$396,5) -> 0 | EA8: 25 | EB8: =VLOOKUP(EA8,$AE$7:$AJ$396,6) -> 0 | ED8: 12 | EE8: =VLOOKUP(ED8,$AE$7:$AJ$396,5) -> 0 | EF8: 147 | EG8: =VLOOKUP(EF8,$AE$7:$AJ$396,6) -> 1 | EI8: 18 | EJ8: =VLOOKUP(EI8,$AE$7:$AJ$396,5) -> 1 | EK8: 127 | EL8: =VLOOKUP(EK8,$AE$7:$AJ$396,6) -> 1 | EN8: 8 | EO8: =VLOOKUP(EN8,$AE$7:$AJ$396,5) -> 0 | EP8: 24 | EQ8: =VLOOKUP(EP8,$AE$7:$AJ$396,6) -> 1 | ES8: 11 | ET8: =VLOOKUP(ES8,$AE$7:$AJ$396,5) -> 0 | EU8: 74 | EV8: =VLOOKUP(EU8,$AE$7:$AJ$396,6) -> 0 | EX8: 7 | EY8: =VLOOKUP(EX8,$AE$7:$AJ$396,5) -> 0 | EZ8: 133 | FA8: =VLOOKUP(EZ8,$AE$7:$AJ$396,6) -> 0 | FC8: 27 | FD8: =VLOOKUP(FC8,$AE$7:$AJ$396,2) -> 1 | FE8: 87 | FF8: =VLOOKUP(FE8,$AE$7:$AJ$396,2) -> 2 | FG8: =IF(FD8<>FF8,1,0) -> 1 | FI8: 133 | FJ8: =VLOOKUP(FI8,$AE$7:$AJ$396,2) -> 1 | FO8: 18 | FP8: =VLOOKUP(FO8,$AE$7:$AJ$396,2) -> 1 | FR8: =IF(OR(AND(FP8=1,FQ8<>"Y"),AND(FP8=2,FQ8="Y")),1,0) -> 1 | FS8: 31 | FT8: =VLOOKUP(FS8,$AE$7:$AJ$396,2) -> 2 | FV8: =IF(OR(AND(FT8=1,FU8<>"Y"),AND(FT8=2,FU8="Y")),1,0) -> 0 | FX8: 204 | FY8: =VLOOKUP(FX8,$AE$7:$AJ$396,5) -> 0 | FZ8: 276 | GA8: =VLOOKUP(FZ8,$AE$7:$AJ$396,6) -> 1
U9: Validity Scales | Y9: Clinic number: | Z9: =C6 | AE9: 3 | AF9: =IF(ISERROR(VALUE(MID($C$11,$AE9,1)))=TRUE,"TEXT",VALUE(MID($C$11,$AE9,1))) -> 2 | AH9: =IF(AF9=9,0,(IF(AG9="Y",AF9-1,2-AF9))) -> 0 | AI9: =IF(AF9=1,1,0) -> 0 | AJ9: =IF(AF9=2,1,0) -> 1 | AL9: 244 | AM9: =VLOOKUP(AL9,$AE$7:$AH$396,4) -> 0 | AO9: 14 | AP9: =VLOOKUP(AO9,$AE$7:$AH$396,4) -> 0 | AR9: 25 | AS9: =VLOOKUP(AR9,$AE$7:$AH$396,4) -> 0 | AU9: 17 | AV9: =VLOOKUP(AU9,$AE$7:$AH$396,4) -> 1 | AX9: 30 | AY9: =VLOOKUP(AX9,$AE$7:$AH$396,4) -> 1 | BA9: 77 | BB9: =VLOOKUP(BA9,$AE$7:$AH$396,4) -> 0 | BD9: 65 | BE9: =VLOOKUP(BD9,$AE$7:$AH$396,4) -> 0 | BG9: 20 | BH9: =VLOOKUP(BG9,$AE$7:$AH$396,4) -> 0 | BJ9: 26 | BK9: =VLOOKUP(BJ9,$AE$7:$AH$396,4) -> 0 | BM9: 239 | BN9: =VLOOKUP(BM9,$AE$7:$AH$396,4) -> 0 | BP9: 19 | BQ9: =VLOOKUP(BP9,$AE$7:$AH$396,4) -> 1 | BS9: 71 | BT9: =VLOOKUP(BS9,$AE$7:$AH$396,4) -> 0 | BV9: 11 | BW9: =VLOOKUP(BV9,$AE$7:$AH$396,4) -> 0 | BY9: 37 | BZ9: =VLOOKUP(BY9,$AE$7:$AH$396,4) -> 0 | CB9: 10 | CC9: =VLOOKUP(CB9,$AE$7:$AH$396,4) -> 1 | CE9: 18 | CF9: =VLOOKUP(CE9,$AE$7:$AH$396,4) -> 1 | CH9: 263 | CI9: =VLOOKUP(CH9,$AE$7:$AH$396,4) -> 0 | CK9: 30 | CL9: =VLOOKUP(CK9,$AE$7:$AJ$396,5) -> 1 | CM9: 10 | CN9: =VLOOKUP(CM9,$AE$7:$AJ$396,6) -> 0 | CP9: 57 | CQ9: =VLOOKUP(CP9,$AE$7:$AJ$396,5) -> 0 | CR9: 25 | CS9: =VLOOKUP(CR9,$AE$7:$AJ$396,6) -> 0 | CU9: 23 | CV9: =VLOOKUP(CU9,$AE$7:$AJ$396,5) -> 0 | CW9: 37 | CX9: =VLOOKUP(CW9,$AE$7:$AJ$396,6) -> 0 | CZ9: 15 | DA9: =VLOOKUP(CZ9,$AE$7:$AJ$396,5) -> 0 | DB9: 158 | DC9: =VLOOKUP(DB9,$AE$7:$AJ$396,6) -> 1 | DE9: 21 | DF9: =VLOOKUP(DE9,$AE$7:$AJ$396,5) -> 0 | DG9: 73 | DH9: =VLOOKUP(DG9,$AE$7:$AJ$396,6) -> 1 | DJ9: 55 | DK9: =VLOOKUP(DJ9,$AE$7:$AJ$396,5) -> 1 | DL9: 26 | DM9: =VLOOKUP(DL9,$AE$7:$AJ$396,6) -> 0 | DO9: 67 | DP9: =VLOOKUP(DO9,$AE$7:$AJ$396,5) -> 0 | DQ9: 237 | DR9: =VLOOKUP(DQ9,$AE$7:$AJ$396,6) -> 1 | DT9: 69 | DU9: =VLOOKUP(DT9,$AE$7:$AJ$396,5) -> 0 | DV9: 82 | DW9: =VLOOKUP(DV9,$AE$7:$AJ$396,6) -> 1 | DY9: 51 | DZ9: =VLOOKUP(DY9,$AE$7:$AJ$396,5) -> 0 | EA9: 82 | EB9: =VLOOKUP(EA9,$AE$7:$AJ$396,6) -> 1 | ED9: 21 | EE9: =VLOOKUP(ED9,$AE$7:$AJ$396,5) -> 0 | EI9: 34 | EJ9: =VLOOKUP(EI9,$AE$7:$AJ$396,5) -> 0 | EK9: 170 | EL9: =VLOOKUP(EK9,$AE$7:$AJ$396,6) -> 1 | EN9: 9 | EO9: =VLOOKUP(EN9,$AE$7:$AJ$396,5) -> 0 | EP9: 133 | EQ9: =VLOOKUP(EP9,$AE$7:$AJ$396,6) -> 0 | ES9: 22 | ET9: =VLOOKUP(ES9,$AE$7:$AJ$396,5) -> 0 | EU9: 101 | EV9: =VLOOKUP(EU9,$AE$7:$AJ$396,6) -> 1 | EX9: 14 | EY9: =VLOOKUP(EX9,$AE$7:$AJ$396,5) -> 0 | EZ9: 199 | FA9: =VLOOKUP(EZ9,$AE$7:$AJ$396,6) -> 0 | FC9: 176 | FD9: =VLOOKUP(FC9,$AE$7:$AJ$396,2) -> 2 | FE9: 205 | FF9: =VLOOKUP(FE9,$AE$7:$AJ$396,2) -> 2 | FG9: =IF(FD9<>FF9,1,0) -> 0 | FI9: 224 | FJ9: =VLOOKUP(FI9,$AE$7:$AJ$396,2) -> 2 | FO9: 25 | FP9: =VLOOKUP(FO9,$AE$7:$AJ$396,2) -> 1 | FQ9: Y | FR9: =IF(OR(AND(FP9=1,FQ9<>"Y"),AND(FP9=2,FQ9="Y")),1,0) -> 0 | FS9: 47 | FT9: =VLOOKUP(FS9,$AE$7:$AJ$396,2) -> 2 | FV9: =IF(OR(AND(FT9=1,FU9<>"Y"),AND(FT9=2,FU9="Y")),1,0) -> 0 | FX9: 212 | FY9: =VLOOKUP(FX9,$AE$7:$AJ$396,5) -> 0 | FZ9: 306 | GA9: =VLOOKUP(FZ9,$AE$7:$AJ$396,6) -> 0
B10: Enter Data here (1 = true; 2 = false, 9 = missing) | U10: VRIN | V10: =FF38 -> 9 | W10: =FF39 -> 67 | Y10: Date of testing: | Z10: =C7 | AE10: 4 | AF10: =IF(ISERROR(VALUE(MID($C$11,$AE10,1)))=TRUE,"TEXT",VALUE(MID($C$11,$AE10,1))) -> 1 | AG10: Y | AH10: =IF(AF10=9,0,(IF(AG10="Y",AF10-1,2-AF10))) -> 0 | AI10: =IF(AF10=1,1,0) -> 1 | AJ10: =IF(AF10=2,1,0) -> 0 | AL10: 245 | AM10: =VLOOKUP(AL10,$AE$7:$AH$396,4) -> 0 | AO10: 27 | AP10: =VLOOKUP(AO10,$AE$7:$AH$396,4) -> 1 | AR10: 33 | AS10: =VLOOKUP(AR10,$AE$7:$AH$396,4) -> 0 | AU10: 21 | AV10: =VLOOKUP(AU10,$AE$7:$AH$396,4) -> 0 | AX10: 65 | AY10: =VLOOKUP(AX10,$AE$7:$AH$396,4) -> 0 | BA10: 98 | BB10: =VLOOKUP(BA10,$AE$7:$AH$396,4) -> 0 | BD10: 110 | BE10: =VLOOKUP(BD10,$AE$7:$AH$396,4) -> 1 | BG10: 42 | BH10: =VLOOKUP(BG10,$AE$7:$AH$396,4) -> 0 | BJ10: 36 | BK10: =VLOOKUP(BJ10,$AE$7:$AH$396,4) -> 0 | BM10: 240 | BN10: =VLOOKUP(BM10,$AE$7:$AH$396,4) -> 1 | BP10: 28 | BQ10: =VLOOKUP(BP10,$AE$7:$AH$396,4) -> 0 | BS10: 83 | BT10: =VLOOKUP(BS10,$AE$7:$AH$396,4) -> 0 | BV10: 22 | BW10: =VLOOKUP(BV10,$AE$7:$AH$396,4) -> 0 | BY10: 41 | BZ10: =VLOOKUP(BY10,$AE$7:$AH$396,4) -> 0 | CB10: 32 | CC10: =VLOOKUP(CB10,$AE$7:$AH$396,4) -> 0 | CE10: 29 | CF10: =VLOOKUP(CE10,$AE$7:$AH$396,4) -> 1 | CH10: 271 | CI10: =VLOOKUP(CH10,$AE$7:$AH$396,4) -> 0 | CK10: 142 | CL10: =VLOOKUP(CK10,$AE$7:$AJ$396,5) -> 0 | CM10: 26 | CN10: =VLOOKUP(CM10,$AE$7:$AJ$396,6) -> 0 | CP10: 88 | CQ10: =VLOOKUP(CP10,$AE$7:$AJ$396,5) -> 0 | CR10: 34 | CS10: =VLOOKUP(CR10,$AE$7:$AJ$396,6) -> 1 | CU10: 56 | CV10: =VLOOKUP(CU10,$AE$7:$AJ$396,5) -> 0 | CW10: 73 | CX10: =VLOOKUP(CW10,$AE$7:$AJ$396,6) -> 1 | CZ10: 19 | DA10: =VLOOKUP(CZ10,$AE$7:$AJ$396,5) -> 0 | DE10: 39 | DF10: =VLOOKUP(DE10,$AE$7:$AJ$396,5) -> 0 | DG10: 185 | DH10: =VLOOKUP(DG10,$AE$7:$AJ$396,6) -> 1 | DJ10: 100 | DK10: =VLOOKUP(DJ10,$AE$7:$AJ$396,5) -> 0 | DL10: 36 | DM10: =VLOOKUP(DL10,$AE$7:$AJ$396,6) -> 0 | DO10: 98 | DP10: =VLOOKUP(DO10,$AE$7:$AJ$396,5) -> 0 | DQ10: 253 | DR10: =VLOOKUP(DQ10,$AE$7:$AJ$396,6) -> 0 | DT10: 100 | DU10: =VLOOKUP(DT10,$AE$7:$AJ$396,5) -> 0 | DV10: 83 | DW10: =VLOOKUP(DV10,$AE$7:$AJ$396,6) -> 0 | DY10: 57 | DZ10: =VLOOKUP(DY10,$AE$7:$AJ$396,5) -> 0 | EA10: 350 | EB10: =VLOOKUP(EA10,$AE$7:$AJ$396,6) -> 1 | ED10: 59 | EE10: =VLOOKUP(ED10,$AE$7:$AJ$396,5) -> 1 | EI10: 71 | EJ10: =VLOOKUP(EI10,$AE$7:$AJ$396,5) -> 0 | EK10: 198 | EL10: =VLOOKUP(EK10,$AE$7:$AJ$396,6) -> 0 | EN10: 14 | EO10: =VLOOKUP(EN10,$AE$7:$AJ$396,5) -> 0 | EP10: 147 | EQ10: =VLOOKUP(EP10,$AE$7:$AJ$396,6) -> 1 | ES10: 35 | ET10: =VLOOKUP(ES10,$AE$7:$AJ$396,5) -> 0 | EU10: 182 | EV10: =VLOOKUP(EU10,$AE$7:$AJ$396,6) -> 0 | EX10: 20 | EY10: =VLOOKUP(EX10,$AE$7:$AJ$396,5) -> 0 | EZ10: 218 | FA10: =VLOOKUP(EZ10,$AE$7:$AJ$396,6) -> 1 | FC10: 25 | FD10: =VLOOKUP(FC10,$AE$7:$AJ$396,2) -> 1 | FE10: 200 | FF10: =VLOOKUP(FE10,$AE$7:$AJ$396,2) -> 1 | FG10: =IF(FD10<>FF10,1,0) -> 0 | FI10: 25 | FJ10: =VLOOKUP(FI10,$AE$7:$AJ$396,2) -> 1 | FO10: 49 | FP10: =VLOOKUP(FO10,$AE$7:$AJ$396,2) -> 2 | FR10: =IF(OR(AND(FP10=1,FQ10<>"Y"),AND(FP10=2,FQ10="Y")),1,0) -> 0 | FS10: 54 | FT10: =VLOOKUP(FS10,$AE$7:$AJ$396,2) -> 2 | FV10: =IF(OR(AND(FT10=1,FU10<>"Y"),AND(FT10=2,FU10="Y")),1,0) -> 0 | FX10: 220 | FY10: =VLOOKUP(FX10,$AE$7:$AJ$396,5) -> 0 | FZ10: 308 | GA10: =VLOOKUP(FZ10,$AE$7:$AJ$396,6) -> 0
B11: Items 1-60 | C11: 222121222122222221222222111211222221122222222222222212122212 | U11: TRIN | V11: =FM38 -> 11 | W11: =FM39 -> 26 | Y11: Clinician: | Z11: =C8 | AE11: 5 | AF11: =IF(ISERROR(VALUE(MID($C$11,$AE11,1)))=TRUE,"TEXT",VALUE(MID($C$11,$AE11,1))) -> 2 | AH11: =IF(AF11=9,0,(IF(AG11="Y",AF11-1,2-AF11))) -> 0 | AI11: =IF(AF11=1,1,0) -> 0 | AJ11: =IF(AF11=2,1,0) -> 1 | AL11: 248 | AM11: =VLOOKUP(AL11,$AE$7:$AH$396,4) -> 0 | AO11: 38 | AP11: =VLOOKUP(AO11,$AE$7:$AH$396,4) -> 0 | AR11: 46 | AS11: =VLOOKUP(AR11,$AE$7:$AH$396,4) -> 0 | AU11: 24 | AV11: =VLOOKUP(AU11,$AE$7:$AH$396,4) -> 1 | AX11: 77 | AY11: =VLOOKUP(AX11,$AE$7:$AH$396,4) -> 0 | BA11: 139 | BB11: =VLOOKUP(BA11,$AE$7:$AH$396,4) -> 1 | BD11: 142 | BE11: =VLOOKUP(BD11,$AE$7:$AH$396,4) -> 0 | BG11: 51 | BH11: =VLOOKUP(BG11,$AE$7:$AH$396,4) -> 0 | BJ11: 40 | BK11: =VLOOKUP(BJ11,$AE$7:$AH$396,4) -> 0 | BM11: 242 | BN11: =VLOOKUP(BM11,$AE$7:$AH$396,4) -> 1 | BP11: 45 | BQ11: =VLOOKUP(BP11,$AE$7:$AH$396,4) -> 1 | BS11: 90 | BT11: =VLOOKUP(BS11,$AE$7:$AH$396,4) -> 0 | BV11: 35 | BW11: =VLOOKUP(BV11,$AE$7:$AH$396,4) -> 0 | BY11: 58 | BZ11: =VLOOKUP(BY11,$AE$7:$AH$396,4) -> 1 | CB11: 34 | CC11: =VLOOKUP(CB11,$AE$7:$AH$396,4) -> 0 | CE11: 47 | CF11: =VLOOKUP(CE11,$AE$7:$AH$396,4) -> 0 | CH11: 280 | CI11: =VLOOKUP(CH11,$AE$7:$AH$396,4) -> 1 | CK11: 2 | CL11: =VLOOKUP(CK11,$AE$7:$AJ$396,5) -> 0 | CM11: 49 | CN11: =VLOOKUP(CM11,$AE$7:$AJ$396,6) -> 1 | CP11: 91 | CQ11: =VLOOKUP(CP11,$AE$7:$AJ$396,5) -> 0 | CR11: 37 | CS11: =VLOOKUP(CR11,$AE$7:$AJ$396,6) -> 0 | CU11: 66 | CV11: =VLOOKUP(CU11,$AE$7:$AJ$396,5) -> 0 | CW11: 80 | CX11: =VLOOKUP(CW11,$AE$7:$AJ$396,6) -> 0 | CZ11: 92 | DA11: =VLOOKUP(CZ11,$AE$7:$AJ$396,5) -> 0 | DE11: 42 | DF11: =VLOOKUP(DE11,$AE$7:$AJ$396,5) -> 0 | DG11: 199 | DH11: =VLOOKUP(DG11,$AE$7:$AJ$396,6) -> 0 | DJ11: 123 | DK11: =VLOOKUP(DJ11,$AE$7:$AJ$396,5) -> 0 | DL11: 62 | DM11: =VLOOKUP(DL11,$AE$7:$AJ$396,6) -> 0 | DO11: 115 | DP11: =VLOOKUP(DO11,$AE$7:$AJ$396,5) -> 0 | DT11: 123 | DU11: =VLOOKUP(DT11,$AE$7:$AJ$396,5) -> 0 | DV11: 145 | DW11: =VLOOKUP(DV11,$AE$7:$AJ$396,6) -> 1 | DY11: 69 | DZ11: =VLOOKUP(DY11,$AE$7:$AJ$396,5) -> 0 | EA11: 368 | EB11: =VLOOKUP(EA11,$AE$7:$AJ$396,6) -> 1 | ED11: 107 | EE11: =VLOOKUP(ED11,$AE$7:$AJ$396,5) -> 0 | EI11: 111 | EJ11: =VLOOKUP(EI11,$AE$7:$AJ$396,5) -> 0 | EK11: 228 | EL11: =VLOOKUP(EK11,$AE$7:$AJ$396,6) -> 1 | EN11: 38 | EO11: =VLOOKUP(EN11,$AE$7:$AJ$396,5) -> 0 | EP11: 148 | EQ11: =VLOOKUP(EP11,$AE$7:$AJ$396,6) -> 0 | ES11: 48 | ET11: =VLOOKUP(ES11,$AE$7:$AJ$396,5) -> 0 | EU11: 218 | EV11: =VLOOKUP(EU11,$AE$7:$AJ$396,6) -> 1 | EX11: 38 | EY11: =VLOOKUP(EX11,$AE$7:$AJ$396,5) -> 0 | FC11: 91 | FD11: =VLOOKUP(FC11,$AE$7:$AJ$396,2) -> 2 | FE11: 102 | FF11: =VLOOKUP(FE11,$AE$7:$AJ$396,2) -> 2 | FG11: =IF(FD11<>FF11,1,0) -> 0 | FI11: 105 | FJ11: =VLOOKUP(FI11,$AE$7:$AJ$396,2) -> 2 | FO11: 79 | FP11: =VLOOKUP(FO11,$AE$7:$AJ$396,2) -> 2 | FR11: =IF(OR(AND(FP11=1,FQ11<>"Y"),AND(FP11=2,FQ11="Y")),1,0) -> 0 | FS11: 84 | FT11: =VLOOKUP(FS11,$AE$7:$AJ$396,2) -> 1 | FU11: Y | FV11: =IF(OR(AND(FT11=1,FU11<>"Y"),AND(FT11=2,FU11="Y")),1,0) -> 0 | FX11: 229 | FY11: =VLOOKUP(FX11,$AE$7:$AJ$396,5) -> 0
B12: Items 61-120 | C12: 112122222222211211212211222212221121222222222222222222222222 | U12: DRIN | V12: =FS30 -> 17 | W12: =FS31 -> 40 | AE12: 6 | AF12: =IF(ISERROR(VALUE(MID($C$11,$AE12,1)))=TRUE,"TEXT",VALUE(MID($C$11,$AE12,1))) -> 1 | AG12: Y | AH12: =IF(AF12=9,0,(IF(AG12="Y",AF12-1,2-AF12))) -> 0 | AI12: =IF(AF12=1,1,0) -> 1 | AJ12: =IF(AF12=2,1,0) -> 0 | AL12: 250 | AM12: =VLOOKUP(AL12,$AE$7:$AH$396,4) -> 0 | AO12: 53 | AP12: =VLOOKUP(AO12,$AE$7:$AH$396,4) -> 1 | AR12: 63 | AS12: =VLOOKUP(AR12,$AE$7:$AH$396,4) -> 1 | AU12: 31 | AV12: =VLOOKUP(AU12,$AE$7:$AH$396,4) -> 0 | AX12: 98 | AY12: =VLOOKUP(AX12,$AE$7:$AH$396,4) -> 0 | BA12: 161 | BB12: =VLOOKUP(BA12,$AE$7:$AH$396,4) -> 1 | BD12: 157 | BE12: =VLOOKUP(BD12,$AE$7:$AH$396,4) -> 0 | BG12: 60 | BH12: =VLOOKUP(BG12,$AE$7:$AH$396,4) -> 0 | BJ12: 44 | BK12: =VLOOKUP(BJ12,$AE$7:$AH$396,4) -> 0 | BM12: 249 | BN12: =VLOOKUP(BM12,$AE$7:$AH$396,4) -> 1 | BP12: 57 | BQ12: =VLOOKUP(BP12,$AE$7:$AH$396,4) -> 0 | BS12: 113 | BT12: =VLOOKUP(BS12,$AE$7:$AH$396,4) -> 0 | BV12: 48 | BW12: =VLOOKUP(BV12,$AE$7:$AH$396,4) -> 0 | BY12: 66 | BZ12: =VLOOKUP(BY12,$AE$7:$AH$396,4) -> 0 | CB12: 50 | CC12: =VLOOKUP(CB12,$AE$7:$AH$396,4) -> 0 | CE12: 54 | CF12: =VLOOKUP(CE12,$AE$7:$AH$396,4) -> 0 | CH12: 286 | CI12: =VLOOKUP(CH12,$AE$7:$AH$396,4) -> 0 | CK12: 149 | CL12: =VLOOKUP(CK12,$AE$7:$AJ$396,5) -> 1 | CM12: 52 | CN12: =VLOOKUP(CM12,$AE$7:$AJ$396,6) -> 1 | CP12: 99 | CQ12: =VLOOKUP(CP12,$AE$7:$AJ$396,5) -> 0 | CR12: 124 | CS12: =VLOOKUP(CR12,$AE$7:$AJ$396,6) -> 0 | CU12: 91 | CV12: =VLOOKUP(CU12,$AE$7:$AJ$396,5) -> 0 | CW12: 146 | CX12: =VLOOKUP(CW12,$AE$7:$AJ$396,6) -> 0 | CZ12: 196 | DA12: =VLOOKUP(CZ12,$AE$7:$AJ$396,5) -> 0 | DE12: 55 | DF12: =VLOOKUP(DE12,$AE$7:$AJ$396,5) -> 1 | DJ12: 197 | DK12: =VLOOKUP(DJ12,$AE$7:$AJ$396,5) -> 0 | DL12: 84 | DM12: =VLOOKUP(DL12,$AE$7:$AJ$396,6) -> 0 | DO12: 139 | DP12: =VLOOKUP(DO12,$AE$7:$AJ$396,5) -> 1 | DT12: 169 | DU12: =VLOOKUP(DT12,$AE$7:$AJ$396,5) -> 0 | DV12: 207 | DW12: =VLOOKUP(DV12,$AE$7:$AJ$396,6) -> 1 | DY12: 108 | DZ12: =VLOOKUP(DY12,$AE$7:$AJ$396,5) -> 0 | ED12: 186 | EE12: =VLOOKUP(ED12,$AE$7:$AJ$396,5) -> 1 | EI12: 124 | EJ12: =VLOOKUP(EI12,$AE$7:$AJ$396,5) -> 1 | EK12: 329 | EL12: =VLOOKUP(EK12,$AE$7:$AJ$396,6) -> 1 | EN12: 53 | EO12: =VLOOKUP(EN12,$AE$7:$AJ$396,5) -> 1 | ES12: 140 | ET12: =VLOOKUP(ES12,$AE$7:$AJ$396,5) -> 0 | EU12: 239 | EV12: =VLOOKUP(EU12,$AE$7:$AJ$396,6) -> 1 | EX12: 48 | EY12: =VLOOKUP(EX12,$AE$7:$AJ$396,5) -> 0 | FC12: 157 | FD12: =VLOOKUP(FC12,$AE$7:$AJ$396,2) -> 2 | FE12: 190 | FF12: =VLOOKUP(FE12,$AE$7:$AJ$396,2) -> 2 | FG12: =IF(FD12<>FF12,1,0) -> 0 | FI12: 129 | FJ12: =VLOOKUP(FI12,$AE$7:$AJ$396,2) -> 2 | FO12: 93 | FP12: =VLOOKUP(FO12,$AE$7:$AJ$396,2) -> 1 | FR12: =IF(OR(AND(FP12=1,FQ12<>"Y"),AND(FP12=2,FQ12="Y")),1,0) -> 1 | FS12: 91 | FT12: =VLOOKUP(FS12,$AE$7:$AJ$396,2) -> 2 | FV12: =IF(OR(AND(FT12=1,FU12<>"Y"),AND(FT12=2,FU12="Y")),1,0) -> 0 | FX12: 230 | FY12: =VLOOKUP(FX12,$AE$7:$AJ$396,5) -> 0
B13: Items 121-180 | C13: 222122222212121222122222212111211211222222211211222221121111 | U13: Rare Virtues | V13: =CI37 -> 3 | W13: =CI38 -> 50 | AE13: 7 | AF13: =IF(ISERROR(VALUE(MID($C$11,$AE13,1)))=TRUE,"TEXT",VALUE(MID($C$11,$AE13,1))) -> 2 | AH13: =IF(AF13=9,0,(IF(AG13="Y",AF13-1,2-AF13))) -> 0 | AI13: =IF(AF13=1,1,0) -> 0 | AJ13: =IF(AF13=2,1,0) -> 1 | AL13: 252 | AM13: =VLOOKUP(AL13,$AE$7:$AH$396,4) -> 0 | AO13: 59 | AP13: =VLOOKUP(AO13,$AE$7:$AH$396,4) -> 1 | AR13: 76 | AS13: =VLOOKUP(AR13,$AE$7:$AH$396,4) -> 0 | AU13: 43 | AV13: =VLOOKUP(AU13,$AE$7:$AH$396,4) -> 0 | AX13: 110 | AY13: =VLOOKUP(AX13,$AE$7:$AH$396,4) -> 1 | BA13: 193 | BB13: =VLOOKUP(BA13,$AE$7:$AH$396,4) -> 0 | BD13: 172 | BE13: =VLOOKUP(BD13,$AE$7:$AH$396,4) -> 0 | BG13: 72 | BH13: =VLOOKUP(BG13,$AE$7:$AH$396,4) -> 0 | BJ13: 52 | BK13: =VLOOKUP(BJ13,$AE$7:$AH$396,4) -> 1 | BM13: 253 | BN13: =VLOOKUP(BM13,$AE$7:$AH$396,4) -> 1 | BP13: 69 | BQ13: =VLOOKUP(BP13,$AE$7:$AH$396,4) -> 0 | BS13: 120 | BT13: =VLOOKUP(BS13,$AE$7:$AH$396,4) -> 0 | BV13: 61 | BW13: =VLOOKUP(BV13,$AE$7:$AH$396,4) -> 0 | BY13: 89 | BZ13: =VLOOKUP(BY13,$AE$7:$AH$396,4) -> 0 | CB13: 64 | CC13: =VLOOKUP(CB13,$AE$7:$AH$396,4) -> 1 | CE13: 68 | CF13: =VLOOKUP(CE13,$AE$7:$AH$396,4) -> 0 | CH13: 296 | CI13: =VLOOKUP(CH13,$AE$7:$AH$396,4) -> 1 | CK13: 79 | CL13: =VLOOKUP(CK13,$AE$7:$AJ$396,5) -> 0 | CM13: 74 | CN13: =VLOOKUP(CM13,$AE$7:$AJ$396,6) -> 0 | CP13: 117 | CQ13: =VLOOKUP(CP13,$AE$7:$AJ$396,5) -> 0 | CR13: 130 | CS13: =VLOOKUP(CR13,$AE$7:$AJ$396,6) -> 1 | CU13: 97 | CV13: =VLOOKUP(CU13,$AE$7:$AJ$396,5) -> 0 | CW13: 225 | CX13: =VLOOKUP(CW13,$AE$7:$AJ$396,6) -> 1 | CZ13: 238 | DA13: =VLOOKUP(CZ13,$AE$7:$AJ$396,5) -> 0 | DE13: 65 | DF13: =VLOOKUP(DE13,$AE$7:$AJ$396,5) -> 0 | DJ13: 313 | DK13: =VLOOKUP(DJ13,$AE$7:$AJ$396,5) -> 0 | DL13: 156 | DM13: =VLOOKUP(DL13,$AE$7:$AJ$396,6) -> 0 | DO13: 193 | DP13: =VLOOKUP(DO13,$AE$7:$AJ$396,5) -> 0 | DT13: 183 | DU13: =VLOOKUP(DT13,$AE$7:$AJ$396,5) -> 0 | DY13: 113 | DZ13: =VLOOKUP(DY13,$AE$7:$AJ$396,5) -> 0 | ED13: 219 | EE13: =VLOOKUP(ED13,$AE$7:$AJ$396,5) -> 0 | EI13: 125 | EJ13: =VLOOKUP(EI13,$AE$7:$AJ$396,5) -> 0 | EN13: 67 | EO13: =VLOOKUP(EN13,$AE$7:$AJ$396,5) -> 0 | ES13: 177 | ET13: =VLOOKUP(ES13,$AE$7:$AJ$396,5) -> 1 | EU13: 249 | EV13: =VLOOKUP(EU13,$AE$7:$AJ$396,6) -> 0 | EX13: 72 | EY13: =VLOOKUP(EX13,$AE$7:$AJ$396,5) -> 0 | FC13: 28 | FD13: =VLOOKUP(FC13,$AE$7:$AJ$396,2) -> 2 | FE13: 183 | FF13: =VLOOKUP(FE13,$AE$7:$AJ$396,2) -> 2 | FG13: =IF(FD13<>FF13,1,0) -> 0 | FI13: 200 | FJ13: =VLOOKUP(FI13,$AE$7:$AJ$396,2) -> 1 | FO13: 95 | FP13: =VLOOKUP(FO13,$AE$7:$AJ$396,2) -> 2 | FR13: =IF(OR(AND(FP13=1,FQ13<>"Y"),AND(FP13=2,FQ13="Y")),1,0) -> 0 | FS13: 105 | FT13: =VLOOKUP(FS13,$AE$7:$AJ$396,2) -> 2 | FV13: =IF(OR(AND(FT13=1,FU13<>"Y"),AND(FT13=2,FU13="Y")),1,0) -> 0 | FX13: 233 | FY13: =VLOOKUP(FX13,$AE$7:$AJ$396,5) -> 0
B14: Items 181-240 | C14: 112121222212222221111122212222222222222222222222222222222221 | U14: Deviance | V14: =CM35 -> 7 | W14: =CM36 -> 71 | AE14: 8 | AF14: =IF(ISERROR(VALUE(MID($C$11,$AE14,1)))=TRUE,"TEXT",VALUE(MID($C$11,$AE14,1))) -> 2 | AH14: =IF(AF14=9,0,(IF(AG14="Y",AF14-1,2-AF14))) -> 0 | AI14: =IF(AF14=1,1,0) -> 0 | AJ14: =IF(AF14=2,1,0) -> 1 | AL14: 259 | AM14: =VLOOKUP(AL14,$AE$7:$AH$396,4) -> 0 | AO14: 67 | AP14: =VLOOKUP(AO14,$AE$7:$AH$396,4) -> 0 | AR14: 88 | AS14: =VLOOKUP(AR14,$AE$7:$AH$396,4) -> 0 | AU14: 56 | AV14: =VLOOKUP(AU14,$AE$7:$AH$396,4) -> 0 | AX14: 139 | AY14: =VLOOKUP(AX14,$AE$7:$AH$396,4) -> 1 | BA14: 237 | BB14: =VLOOKUP(BA14,$AE$7:$AH$396,4) -> 1 | BD14: 174 | BE14: =VLOOKUP(BD14,$AE$7:$AH$396,4) -> 1 | BG14: 86 | BH14: =VLOOKUP(BG14,$AE$7:$AH$396,4) -> 0 | BJ14: 62 | BK14: =VLOOKUP(BJ14,$AE$7:$AH$396,4) -> 0 | BM14: 256 | BN14: =VLOOKUP(BM14,$AE$7:$AH$396,4) -> 1 | BP14: 82 | BQ14: =VLOOKUP(BP14,$AE$7:$AH$396,4) -> 1 | BS14: 125 | BT14: =VLOOKUP(BS14,$AE$7:$AH$396,4) -> 0 | BV14: 74 | BW14: =VLOOKUP(BV14,$AE$7:$AH$396,4) -> 0 | BY14: 99 | BZ14: =VLOOKUP(BY14,$AE$7:$AH$396,4) -> 0 | CB14: 78 | CC14: =VLOOKUP(CB14,$AE$7:$AH$396,4) -> 1 | CE14: 79 | CF14: =VLOOKUP(CE14,$AE$7:$AH$396,4) -> 0 | CH14: 305 | CI14: =VLOOKUP(CH14,$AE$7:$AH$396,4) -> 0 | CK14: 43 | CL14: =VLOOKUP(CK14,$AE$7:$AJ$396,5) -> 0 | CM14: 77 | CN14: =VLOOKUP(CM14,$AE$7:$AJ$396,6) -> 0 | CP14: 164 | CQ14: =VLOOKUP(CP14,$AE$7:$AJ$396,5) -> 1 | CR14: 154 | CS14: =VLOOKUP(CR14,$AE$7:$AJ$396,6) -> 1 | CU14: 102 | CV14: =VLOOKUP(CU14,$AE$7:$AJ$396,5) -> 0 | CW14: 251 | CX14: =VLOOKUP(CW14,$AE$7:$AJ$396,6) -> 0 | CZ14: 265 | DA14: =VLOOKUP(CZ14,$AE$7:$AJ$396,5) -> 0 | DE14: 72 | DF14: =VLOOKUP(DE14,$AE$7:$AJ$396,5) -> 0 | DJ14: 327 | DK14: =VLOOKUP(DJ14,$AE$7:$AJ$396,5) -> 0 | DO14: 215 | DP14: =VLOOKUP(DO14,$AE$7:$AJ$396,5) -> 0 | DT14: 217 | DU14: =VLOOKUP(DT14,$AE$7:$AJ$396,5) -> 0 | DY14: 119 | DZ14: =VLOOKUP(DY14,$AE$7:$AJ$396,5) -> 0 | ED14: 246 | EE14: =VLOOKUP(ED14,$AE$7:$AJ$396,5) -> 0 | EI14: 138 | EJ14: =VLOOKUP(EI14,$AE$7:$AJ$396,5) -> 0 | EN14: 87 | EO14: =VLOOKUP(EN14,$AE$7:$AJ$396,5) -> 0 | ES14: 196 | ET14: =VLOOKUP(ES14,$AE$7:$AJ$396,5) -> 0 | EU14: 304 | EV14: =VLOOKUP(EU14,$AE$7:$AJ$396,6) -> 1 | EX14: 86 | EY14: =VLOOKUP(EX14,$AE$7:$AJ$396,5) -> 0 | FC14: 93 | FD14: =VLOOKUP(FC14,$AE$7:$AJ$396,2) -> 1 | FE14: 108 | FF14: =VLOOKUP(FE14,$AE$7:$AJ$396,2) -> 2 | FG14: =IF(FD14<>FF14,1,0) -> 1 | FI14: 109 | FJ14: =VLOOKUP(FI14,$AE$7:$AJ$396,2) -> 2 | FO14: 102 | FP14: =VLOOKUP(FO14,$AE$7:$AJ$396,2) -> 2 | FR14: =IF(OR(AND(FP14=1,FQ14<>"Y"),AND(FP14=2,FQ14="Y")),1,0) -> 0 | FS14: 108 | FT14: =VLOOKUP(FS14,$AE$7:$AJ$396,2) -> 2 | FV14: =IF(OR(AND(FT14=1,FU14<>"Y"),AND(FT14=2,FU14="Y")),1,0) -> 0 | FX14: 243 | FY14: =VLOOKUP(FX14,$AE$7:$AJ$396,5) -> 0
B15: Items 241-300 | C15: 212222221212112112222211222222222222222222212222222222122221 | U15: Back Deviance | V15: =FZ35 -> 1 | W15: =FZ36 -> 48 | Y15: =B19 -> Error Flags | AE15: 9 | AF15: =IF(ISERROR(VALUE(MID($C$11,$AE15,1)))=TRUE,"TEXT",VALUE(MID($C$11,$AE15,1))) -> 2 | AH15: =IF(AF15=9,0,(IF(AG15="Y",AF15-1,2-AF15))) -> 0 | AI15: =IF(AF15=1,1,0) -> 0 | AJ15: =IF(AF15=2,1,0) -> 1 | AL15: 260 | AM15: =VLOOKUP(AL15,$AE$7:$AH$396,4) -> 0 | AO15: 87 | AP15: =VLOOKUP(AO15,$AE$7:$AH$396,4) -> 0 | AR15: 91 | AS15: =VLOOKUP(AR15,$AE$7:$AH$396,4) -> 0 | AU15: 70 | AV15: =VLOOKUP(AU15,$AE$7:$AH$396,4) -> 0 | AX15: 142 | AY15: =VLOOKUP(AX15,$AE$7:$AH$396,4) -> 0 | BD15: 190 | BE15: =VLOOKUP(BD15,$AE$7:$AH$396,4) -> 0 | BG15: 103 | BH15: =VLOOKUP(BG15,$AE$7:$AH$396,4) -> 0 | BJ15: 75 | BK15: =VLOOKUP(BJ15,$AE$7:$AH$396,4) -> 1 | BM15: 257 | BN15: =VLOOKUP(BM15,$AE$7:$AH$396,4) -> 1 | BP15: 93 | BQ15: =VLOOKUP(BP15,$AE$7:$AH$396,4) -> 1 | BS15: 132 | BT15: =VLOOKUP(BS15,$AE$7:$AH$396,4) -> 0 | BV15: 92 | BW15: =VLOOKUP(BV15,$AE$7:$AH$396,4) -> 0 | BY15: 114 | BZ15: =VLOOKUP(BY15,$AE$7:$AH$396,4) -> 0 | CB15: 85 | CC15: =VLOOKUP(CB15,$AE$7:$AH$396,4) -> 0 | CE15: 111 | CF15: =VLOOKUP(CE15,$AE$7:$AH$396,4) -> 0 | CH15: 314 | CI15: =VLOOKUP(CH15,$AE$7:$AH$396,4) -> 0 | CK15: 105 | CL15: =VLOOKUP(CK15,$AE$7:$AJ$396,5) -> 0 | CM15: 84 | CN15: =VLOOKUP(CM15,$AE$7:$AJ$396,6) -> 0 | CP15: 186 | CQ15: =VLOOKUP(CP15,$AE$7:$AJ$396,5) -> 1 | CR15: 160 | CS15: =VLOOKUP(CR15,$AE$7:$AJ$396,6) -> 1 | CU15: 104 | CV15: =VLOOKUP(CU15,$AE$7:$AJ$396,5) -> 0 | CW15: 311 | CX15: =VLOOKUP(CW15,$AE$7:$AJ$396,6) -> 1 | CZ15: 281 | DA15: =VLOOKUP(CZ15,$AE$7:$AJ$396,5) -> 0 | DE15: 134 | DF15: =VLOOKUP(DE15,$AE$7:$AJ$396,5) -> 0 | DJ15: 340 | DK15: =VLOOKUP(DJ15,$AE$7:$AJ$396,5) -> 0 | DO15: 216 | DP15: =VLOOKUP(DO15,$AE$7:$AJ$396,5) -> 0 | DT15: 218 | DU15: =VLOOKUP(DT15,$AE$7:$AJ$396,5) -> 0 | DY15: 120 | DZ15: =VLOOKUP(DY15,$AE$7:$AJ$396,5) -> 0 | ED15: 267 | EE15: =VLOOKUP(ED15,$AE$7:$AJ$396,5) -> 0 | EI15: 160 | EJ15: =VLOOKUP(EI15,$AE$7:$AJ$396,5) -> 0 | EN15: 96 | EO15: =VLOOKUP(EN15,$AE$7:$AJ$396,5) -> 1 | ES15: 233 | ET15: =VLOOKUP(ES15,$AE$7:$AJ$396,5) -> 0 | EU15: 341 | EV15: =VLOOKUP(EU15,$AE$7:$AJ$396,6) -> 1 | EX15: 121 | EY15: =VLOOKUP(EX15,$AE$7:$AJ$396,5) -> 0 | FC15: 132 | FD15: =VLOOKUP(FC15,$AE$7:$AJ$396,2) -> 2 | FE15: 203 | FF15: =VLOOKUP(FE15,$AE$7:$AJ$396,2) -> 2 | FG15: =IF(FD15<>FF15,1,0) -> 0 | FI15: 194 | FJ15: =VLOOKUP(FI15,$AE$7:$AJ$396,2) -> 2 | FO15: 116 | FP15: =VLOOKUP(FO15,$AE$7:$AJ$396,2) -> 2 | FR15: =IF(OR(AND(FP15=1,FQ15<>"Y"),AND(FP15=2,FQ15="Y")),1,0) -> 0 | FS15: 127 | FT15: =VLOOKUP(FS15,$AE$7:$AJ$396,2) -> 2 | FU15: Y | FV15: =IF(OR(AND(FT15=1,FU15<>"Y"),AND(FT15=2,FU15="Y")),1,0) -> 1 | FX15: 268 | FY15: =VLOOKUP(FX15,$AE$7:$AJ$396,5) -> 0
B16: Items 301-360 | C16: 222221212221212212122211212121122222211221212222222222222222 | U16: Invalidity Index | V16: =V14+V13+V10+FM41+FS33 -> 28 | W16: =(((V16-16.2)/5)*10)+50 -> 74 | Y16: =B20 -> Wrong Characters: | Z16: =C20 -> 0 | AB16: =IF(OR($Z$16>0,$Z$17>0),"D A T A E N T R Y","") | AE16: 10 | AF16: =IF(ISERROR(VALUE(MID($C$11,$AE16,1)))=TRUE,"TEXT",VALUE(MID($C$11,$AE16,1))) -> 1 | AH16: =IF(AF16=9,0,(IF(AG16="Y",AF16-1,2-AF16))) -> 1 | AI16: =IF(AF16=1,1,0) -> 1 | AJ16: =IF(AF16=2,1,0) -> 0 | AL16: 264 | AM16: =VLOOKUP(AL16,$AE$7:$AH$396,4) -> 1 | AO16: 106 | AP16: =VLOOKUP(AO16,$AE$7:$AH$396,4) -> 0 | AR16: 102 | AS16: =VLOOKUP(AR16,$AE$7:$AH$396,4) -> 0 | AU16: 80 | AV16: =VLOOKUP(AU16,$AE$7:$AH$396,4) -> 0 | AX16: 157 | AY16: =VLOOKUP(AX16,$AE$7:$AH$396,4) -> 0 | BD16: 206 | BE16: =VLOOKUP(BD16,$AE$7:$AH$396,4) -> 0 | BG16: 128 | BH16: =VLOOKUP(BG16,$AE$7:$AH$396,4) -> 0 | BJ16: 81 | BK16: =VLOOKUP(BJ16,$AE$7:$AH$396,4) -> 0 | BM16: 262 | BN16: =VLOOKUP(BM16,$AE$7:$AH$396,4) -> 0 | BP16: 108 | BQ16: =VLOOKUP(BP16,$AE$7:$AH$396,4) -> 0 | BS16: 143 | BT16: =VLOOKUP(BS16,$AE$7:$AH$396,4) -> 0 | BV16: 101 | BW16: =VLOOKUP(BV16,$AE$7:$AH$396,4) -> 1 | BY16: 126 | BZ16: =VLOOKUP(BY16,$AE$7:$AH$396,4) -> 1 | CB16: 94 | CC16: =VLOOKUP(CB16,$AE$7:$AH$396,4) -> 0 | CE16: 116 | CF16: =VLOOKUP(CE16,$AE$7:$AH$396,4) -> 0 | CH16: 322 | CI16: =VLOOKUP(CH16,$AE$7:$AH$396,4) -> 0 | CM16: 85 | CN16: =VLOOKUP(CM16,$AE$7:$AJ$396,6) -> 1 | CP16: 198 | CQ16: =VLOOKUP(CP16,$AE$7:$AJ$396,5) -> 1 | CR16: 168 | CS16: =VLOOKUP(CR16,$AE$7:$AJ$396,6) -> 0 | CU16: 114 | CV16: =VLOOKUP(CU16,$AE$7:$AJ$396,5) -> 0 | CZ16: 292 | DA16: =VLOOKUP(CZ16,$AE$7:$AJ$396,5) -> 0 | DE16: 142 | DF16: =VLOOKUP(DE16,$AE$7:$AJ$396,5) -> 0 | DJ16: 355 | DK16: =VLOOKUP(DJ16,$AE$7:$AJ$396,5) -> 0 | DO16: 244 | DP16: =VLOOKUP(DO16,$AE$7:$AJ$396,5) -> 0 | DT16: 223 | DU16: =VLOOKUP(DT16,$AE$7:$AJ$396,5) -> 0 | DY16: 125 | DZ16: =VLOOKUP(DY16,$AE$7:$AJ$396,5) -> 0 | ED16: 274 | EE16: =VLOOKUP(ED16,$AE$7:$AJ$396,5) -> 0 | EI16: 180 | EJ16: =VLOOKUP(EI16,$AE$7:$AJ$396,5) -> 1 | EN16: 121 | EO16: =VLOOKUP(EN16,$AE$7:$AJ$396,5) -> 0 | ES16: 278 | ET16: =VLOOKUP(ES16,$AE$7:$AJ$396,5) -> 0 | EX16: 128 | EY16: =VLOOKUP(EX16,$AE$7:$AJ$396,5) -> 0 | FC16: 49 | FD16: =VLOOKUP(FC16,$AE$7:$AJ$396,2) -> 2 | FE16: 171 | FF16: =VLOOKUP(FE16,$AE$7:$AJ$396,2) -> 2 | FG16: =IF(FD16<>FF16,1,0) -> 0 | FI16: 31 | FJ16: =VLOOKUP(FI16,$AE$7:$AJ$396,2) -> 2 | FO16: 132 | FP16: =VLOOKUP(FO16,$AE$7:$AJ$396,2) -> 2 | FR16: =IF(OR(AND(FP16=1,FQ16<>"Y"),AND(FP16=2,FQ16="Y")),1,0) -> 0 | FS16: 136 | FT16: =VLOOKUP(FS16,$AE$7:$AJ$396,2) -> 2 | FU16: Y | FV16: =IF(OR(AND(FT16=1,FU16<>"Y"),AND(FT16=2,FU16="Y")),1,0) -> 1 | FX16: 313 | FY16: =VLOOKUP(FX16,$AE$7:$AJ$396,5) -> 0
B17: Items 361-390 | C17: 221222222222222222222222222222 | Y17: =B21 -> Line Length Errors: | Z17: =C21 -> 0 | AB17: =IF(OR($Z$16>0,$Z$17>0),"E R R O R !","") | AE17: 11 | AF17: =IF(ISERROR(VALUE(MID($C$11,$AE17,1)))=TRUE,"TEXT",VALUE(MID($C$11,$AE17,1))) -> 2 | AH17: =IF(AF17=9,0,(IF(AG17="Y",AF17-1,2-AF17))) -> 0 | AI17: =IF(AF17=1,1,0) -> 0 | AJ17: =IF(AF17=2,1,0) -> 1 | AL17: 269 | AM17: =VLOOKUP(AL17,$AE$7:$AH$396,4) -> 0 | AO17: 121 | AP17: =VLOOKUP(AO17,$AE$7:$AH$396,4) -> 0 | AR17: 104 | AS17: =VLOOKUP(AR17,$AE$7:$AH$396,4) -> 0 | AU17: 96 | AV17: =VLOOKUP(AU17,$AE$7:$AH$396,4) -> 1 | AX17: 161 | AY17: =VLOOKUP(AX17,$AE$7:$AH$396,4) -> 1 | BG17: 150 | BH17: =VLOOKUP(BG17,$AE$7:$AH$396,4) -> 1 | BJ17: 84 | BK17: =VLOOKUP(BJ17,$AE$7:$AH$396,4) -> 0 | BM17: 266 | BN17: =VLOOKUP(BM17,$AE$7:$AH$396,4) -> 0 | BP17: 137 | BQ17: =VLOOKUP(BP17,$AE$7:$AH$396,4) -> 1 | BS17: 155 | BT17: =VLOOKUP(BS17,$AE$7:$AH$396,4) -> 1 | BV17: 131 | BW17: =VLOOKUP(BV17,$AE$7:$AH$396,4) -> 0 | BY17: 130 | BZ17: =VLOOKUP(BY17,$AE$7:$AH$396,4) -> 1 | CB17: 115 | CC17: =VLOOKUP(CB17,$AE$7:$AH$396,4) -> 0 | CE17: 127 | CF17: =VLOOKUP(CE17,$AE$7:$AH$396,4) -> 1 | CH17: 330 | CI17: =VLOOKUP(CH17,$AE$7:$AH$396,4) -> 0 | CM17: 113 | CN17: =VLOOKUP(CM17,$AE$7:$AJ$396,6) -> 1 | CP17: 204 | CQ17: =VLOOKUP(CP17,$AE$7:$AJ$396,5) -> 0 | CR17: 173 | CS17: =VLOOKUP(CR17,$AE$7:$AJ$396,6) -> 1 | CU17: 117 | CV17: =VLOOKUP(CU17,$AE$7:$AJ$396,5) -> 0 | CZ17: 338 | DA17: =VLOOKUP(CZ17,$AE$7:$AJ$396,5) -> 1 | DE17: 150 | DF17: =VLOOKUP(DE17,$AE$7:$AJ$396,5) -> 1 | DJ17: 357 | DK17: =VLOOKUP(DJ17,$AE$7:$AJ$396,5) -> 0 | DO17: 250 | DP17: =VLOOKUP(DO17,$AE$7:$AJ$396,5) -> 0 | DT17: 245 | DU17: =VLOOKUP(DT17,$AE$7:$AJ$396,5) -> 0 | DY17: 143 | DZ17: =VLOOKUP(DY17,$AE$7:$AJ$396,5) -> 0 | ED17: 309 | EE17: =VLOOKUP(ED17,$AE$7:$AJ$396,5) -> 0 | EI17: 187 | EJ17: =VLOOKUP(EI17,$AE$7:$AJ$396,5) -> 0 | EN17: 122 | EO17: =VLOOKUP(EN17,$AE$7:$AJ$396,5) -> 0 | ES17: 295 | ET17: =VLOOKUP(ES17,$AE$7:$AJ$396,5) -> 1 | EX17: 140 | EY17: =VLOOKUP(EX17,$AE$7:$AJ$396,5) -> 0 | FC17: 143 | FD17: =VLOOKUP(FC17,$AE$7:$AJ$396,2) -> 2 | FE17: 155 | FF17: =VLOOKUP(FE17,$AE$7:$AJ$396,2) -> 1 | FG17: =IF(FD17<>FF17,1,0) -> 1 | FI17: 181 | FJ17: =VLOOKUP(FI17,$AE$7:$AJ$396,2) -> 1 | FO17: 151 | FP17: =VLOOKUP(FO17,$AE$7:$AJ$396,2) -> 2 | FR17: =IF(OR(AND(FP17=1,FQ17<>"Y"),AND(FP17=2,FQ17="Y")),1,0) -> 0 | FS17: 141 | FT17: =VLOOKUP(FS17,$AE$7:$AJ$396,2) -> 2 | FV17: =IF(OR(AND(FT17=1,FU17<>"Y"),AND(FT17=2,FU17="Y")),1,0) -> 0 | FX17: 315 | FY17: =VLOOKUP(FX17,$AE$7:$AJ$396,5) -> 0
U18: T&T Scales | Y18: =B22 -> Missing Values: | Z18: =C22 -> 0 | AE18: 12 | AF18: =IF(ISERROR(VALUE(MID($C$11,$AE18,1)))=TRUE,"TEXT",VALUE(MID($C$11,$AE18,1))) -> 2 | AH18: =IF(AF18=9,0,(IF(AG18="Y",AF18-1,2-AF18))) -> 0 | AI18: =IF(AF18=1,1,0) -> 0 | AJ18: =IF(AF18=2,1,0) -> 1 | AL18: 273 | AM18: =VLOOKUP(AL18,$AE$7:$AH$396,4) -> 0 | AO18: 133 | AP18: =VLOOKUP(AO18,$AE$7:$AH$396,4) -> 0 | AR18: 105 | AS18: =VLOOKUP(AR18,$AE$7:$AH$396,4) -> 0 | AU18: 109 | AV18: =VLOOKUP(AU18,$AE$7:$AH$396,4) -> 1 | AX18: 172 | AY18: =VLOOKUP(AX18,$AE$7:$AH$396,4) -> 0 | BG18: 162 | BH18: =VLOOKUP(BG18,$AE$7:$AH$396,4) -> 0 | BJ18: 95 | BK18: =VLOOKUP(BJ18,$AE$7:$AH$396,4) -> 0 | BM18: 270 | BN18: =VLOOKUP(BM18,$AE$7:$AH$396,4) -> 0 | BP18: 145 | BQ18: =VLOOKUP(BP18,$AE$7:$AH$396,4) -> 1 | BS18: 167 | BT18: =VLOOKUP(BS18,$AE$7:$AH$396,4) -> 1 | BV18: 140 | BW18: =VLOOKUP(BV18,$AE$7:$AH$396,4) -> 0 | BY18: 138 | BZ18: =VLOOKUP(BY18,$AE$7:$AH$396,4) -> 1 | CB18: 124 | CC18: =VLOOKUP(CB18,$AE$7:$AH$396,4) -> 1 | CE18: 168 | CF18: =VLOOKUP(CE18,$AE$7:$AH$396,4) -> 1 | CH18: 347 | CI18: =VLOOKUP(CH18,$AE$7:$AH$396,4) -> 1 | CM18: 131 | CN18: =VLOOKUP(CM18,$AE$7:$AJ$396,6) -> 0 | CP18: 208 | CQ18: =VLOOKUP(CP18,$AE$7:$AJ$396,5) -> 0 | CR18: 200 | CS18: =VLOOKUP(CR18,$AE$7:$AJ$396,6) -> 0 | CU18: 118 | CV18: =VLOOKUP(CU18,$AE$7:$AJ$396,5) -> 0 | CZ18: 345 | DA18: =VLOOKUP(CZ18,$AE$7:$AJ$396,5) -> 0 | DE18: 163 | DF18: =VLOOKUP(DE18,$AE$7:$AJ$396,5) -> 0 | DJ18: 380 | DK18: =VLOOKUP(DJ18,$AE$7:$AJ$396,5) -> 0 | DO18: 259 | DP18: =VLOOKUP(DO18,$AE$7:$AJ$396,5) -> 0 | DT18: 293 | DU18: =VLOOKUP(DT18,$AE$7:$AJ$396,5) -> 0 | DY18: 149 | DZ18: =VLOOKUP(DY18,$AE$7:$AJ$396,5) -> 1 | ED18: 321 | EE18: =VLOOKUP(ED18,$AE$7:$AJ$396,5) -> 0 | EI18: 192 | EJ18: =VLOOKUP(EI18,$AE$7:$AJ$396,5) -> 0 | EN18: 163 | EO18: =VLOOKUP(EN18,$AE$7:$AJ$396,5) -> 0 | ES18: 346 | ET18: =VLOOKUP(ES18,$AE$7:$AJ$396,5) -> 0 | EX18: 150 | EY18: =VLOOKUP(EX18,$AE$7:$AJ$396,5) -> 1 | FC18: 9 | FD18: =VLOOKUP(FC18,$AE$7:$AJ$396,2) -> 2 | FE18: 196 | FF18: =VLOOKUP(FE18,$AE$7:$AJ$396,2) -> 2 | FG18: =IF(FD18<>FF18,1,0) -> 0 | FI18: 212 | FJ18: =VLOOKUP(FI18,$AE$7:$AJ$396,2) -> 2 | FO18: 153 | FP18: =VLOOKUP(FO18,$AE$7:$AJ$396,2) -> 1 | FQ18: Y | FR18: =IF(OR(AND(FP18=1,FQ18<>"Y"),AND(FP18=2,FQ18="Y")),1,0) -> 0 | FS18: 167 | FT18: =VLOOKUP(FS18,$AE$7:$AJ$396,2) -> 1 | FV18: =IF(OR(AND(FT18=1,FU18<>"Y"),AND(FT18=2,FU18="Y")),1,0) -> 1 | FX18: 361 | FY18: =VLOOKUP(FX18,$AE$7:$AJ$396,5) -> 0
B19: Error Flags | U19: Negative Temperament | V19: =AM37 -> 3 | W19: =AM38 -> 40 | AE19: 13 | AF19: =IF(ISERROR(VALUE(MID($C$11,$AE19,1)))=TRUE,"TEXT",VALUE(MID($C$11,$AE19,1))) -> 2 | AH19: =IF(AF19=9,0,(IF(AG19="Y",AF19-1,2-AF19))) -> 0 | AI19: =IF(AF19=1,1,0) -> 0 | AJ19: =IF(AF19=2,1,0) -> 1 | AL19: 274 | AM19: =VLOOKUP(AL19,$AE$7:$AH$396,4) -> 0 | AO19: 144 | AP19: =VLOOKUP(AO19,$AE$7:$AH$396,4) -> 0 | AR19: 119 | AS19: =VLOOKUP(AR19,$AE$7:$AH$396,4) -> 0 | AU19: 122 | AV19: =VLOOKUP(AU19,$AE$7:$AH$396,4) -> 0 | AX19: 174 | AY19: =VLOOKUP(AX19,$AE$7:$AH$396,4) -> 1 | BG19: 178 | BH19: =VLOOKUP(BG19,$AE$7:$AH$396,4) -> 1 | BJ19: 100 | BK19: =VLOOKUP(BJ19,$AE$7:$AH$396,4) -> 0 | BM19: 276 | BN19: =VLOOKUP(BM19,$AE$7:$AH$396,4) -> 0 | BP19: 169 | BQ19: =VLOOKUP(BP19,$AE$7:$AH$396,4) -> 0 | BS19: 171 | BT19: =VLOOKUP(BS19,$AE$7:$AH$396,4) -> 0 | BV19: 158 | BW19: =VLOOKUP(BV19,$AE$7:$AH$396,4) -> 1 | BY19: 146 | BZ19: =VLOOKUP(BY19,$AE$7:$AH$396,4) -> 0 | CB19: 135 | CC19: =VLOOKUP(CB19,$AE$7:$AH$396,4) -> 1 | CE19: 180 | CF19: =VLOOKUP(CE19,$AE$7:$AH$396,4) -> 1 | CH19: 359 | CI19: =VLOOKUP(CH19,$AE$7:$AH$396,4) -> 0 | CM19: 200 | CN19: =VLOOKUP(CM19,$AE$7:$AJ$396,6) -> 0 | CP19: 220 | CQ19: =VLOOKUP(CP19,$AE$7:$AJ$396,5) -> 0 | CR19: 251 | CS19: =VLOOKUP(CR19,$AE$7:$AJ$396,6) -> 0 | CU19: 129 | CV19: =VLOOKUP(CU19,$AE$7:$AJ$396,5) -> 0 | CZ19: 354 | DA19: =VLOOKUP(CZ19,$AE$7:$AJ$396,5) -> 0 | DE19: 165 | DF19: =VLOOKUP(DE19,$AE$7:$AJ$396,5) -> 1 | DJ19: 386 | DK19: =VLOOKUP(DJ19,$AE$7:$AJ$396,5) -> 0 | DO19: 281 | DP19: =VLOOKUP(DO19,$AE$7:$AJ$396,5) -> 0 | DT19: 301 | DU19: =VLOOKUP(DT19,$AE$7:$AJ$396,5) -> 0 | DY19: 155 | DZ19: =VLOOKUP(DY19,$AE$7:$AJ$396,5) -> 1 | ED19: 333 | EE19: =VLOOKUP(ED19,$AE$7:$AJ$396,5) -> 0 | EI19: 202 | EJ19: =VLOOKUP(EI19,$AE$7:$AJ$396,5) -> 1 | EN19: 176 | EO19: =VLOOKUP(EN19,$AE$7:$AJ$396,5) -> 0 | ES19: 368 | ET19: =VLOOKUP(ES19,$AE$7:$AJ$396,5) -> 0 | EX19: 162 | EY19: =VLOOKUP(EX19,$AE$7:$AJ$396,5) -> 0 | FC19: 52 | FD19: =VLOOKUP(FC19,$AE$7:$AJ$396,2) -> 2 | FE19: 62 | FF19: =VLOOKUP(FE19,$AE$7:$AJ$396,2) -> 1 | FG19: =IF(FD19<>FF19,1,0) -> 1 | FI19: 225 | FJ19: =VLOOKUP(FI19,$AE$7:$AJ$396,2) -> 2 | FO19: 155 | FP19: =VLOOKUP(FO19,$AE$7:$AJ$396,2) -> 1 | FR19: =IF(OR(AND(FP19=1,FQ19<>"Y"),AND(FP19=2,FQ19="Y")),1,0) -> 1 | FS19: 171 | FT19: =VLOOKUP(FS19,$AE$7:$AJ$396,2) -> 2 | FV19: =IF(OR(AND(FT19=1,FU19<>"Y"),AND(FT19=2,FU19="Y")),1,0) -> 0 | FX19: 370 | FY19: =VLOOKUP(FX19,$AE$7:$AJ$396,5) -> 0
B20: Wrong Characters: | C20: =COUNTIF(AF7:AF396,"<1")+COUNTIF(AF7:AF396,">2")-COUNTIF(AF7:AF396,9)+COUNTIF(AF7:AF396,"TEXT") -> 0 | U20: Mistrust | V20: =AP37 -> 4 | W20: =AP38 -> 49 | Z20: Scores | AB20: No. of | AC20: Meet | AE20: 14 | AF20: =IF(ISERROR(VALUE(MID($C$11,$AE20,1)))=TRUE,"TEXT",VALUE(MID($C$11,$AE20,1))) -> 2 | AH20: =IF(AF20=9,0,(IF(AG20="Y",AF20-1,2-AF20))) -> 0 | AI20: =IF(AF20=1,1,0) -> 0 | AJ20: =IF(AF20=2,1,0) -> 1 | AL20: 277 | AM20: =VLOOKUP(AL20,$AE$7:$AH$396,4) -> 0 | AO20: 147 | AP20: =VLOOKUP(AO20,$AE$7:$AH$396,4) -> 1 | AR20: 129 | AS20: =VLOOKUP(AR20,$AE$7:$AH$396,4) -> 0 | AU20: 141 | AV20: =VLOOKUP(AU20,$AE$7:$AH$396,4) -> 0 | AX20: 190 | AY20: =VLOOKUP(AX20,$AE$7:$AH$396,4) -> 0 | BG20: 199 | BH20: =VLOOKUP(BG20,$AE$7:$AH$396,4) -> 0 | BJ20: 112 | BK20: =VLOOKUP(BJ20,$AE$7:$AH$396,4) -> 1 | BM20: 279 | BN20: =VLOOKUP(BM20,$AE$7:$AH$396,4) -> 0 | BP20: 183 | BQ20: =VLOOKUP(BP20,$AE$7:$AH$396,4) -> 0 | BS20: 179 | BT20: =VLOOKUP(BS20,$AE$7:$AH$396,4) -> 1 | BV20: 170 | BW20: =VLOOKUP(BV20,$AE$7:$AH$396,4) -> 1 | BY20: 154 | BZ20: =VLOOKUP(BY20,$AE$7:$AH$396,4) -> 1 | CB20: 151 | CC20: =VLOOKUP(CB20,$AE$7:$AH$396,4) -> 0 | CE20: 187 | CF20: =VLOOKUP(CE20,$AE$7:$AH$396,4) -> 0 | CP20: 232 | CQ20: =VLOOKUP(CP20,$AE$7:$AJ$396,5) -> 0 | CR20: 254 | CS20: =VLOOKUP(CR20,$AE$7:$AJ$396,6) -> 0 | CU20: 152 | CV20: =VLOOKUP(CU20,$AE$7:$AJ$396,5) -> 1 | CZ20: 364 | DA20: =VLOOKUP(CZ20,$AE$7:$AJ$396,5) -> 0 | DE20: 174 | DF20: =VLOOKUP(DE20,$AE$7:$AJ$396,5) -> 1 | DJ20: 389 | DK20: =VLOOKUP(DJ20,$AE$7:$AJ$396,5) -> 0 | DO20: 288 | DP20: =VLOOKUP(DO20,$AE$7:$AJ$396,5) -> 0 | DT20: 333 | DU20: =VLOOKUP(DT20,$AE$7:$AJ$396,5) -> 0 | DY20: 167 | DZ20: =VLOOKUP(DY20,$AE$7:$AJ$396,5) -> 1 | ED20: 351 | EE20: =VLOOKUP(ED20,$AE$7:$AJ$396,5) -> 0 | EI20: 234 | EJ20: =VLOOKUP(EI20,$AE$7:$AJ$396,5) -> 0 | EN20: 188 | EO20: =VLOOKUP(EN20,$AE$7:$AJ$396,5) -> 0 | ES20: 381 | ET20: =VLOOKUP(ES20,$AE$7:$AJ$396,5) -> 0 | EX20: 163 | EY20: =VLOOKUP(EX20,$AE$7:$AJ$396,5) -> 0 | FC20: 136 | FD20: =VLOOKUP(FC20,$AE$7:$AJ$396,2) -> 2 | FE20: 156 | FF20: =VLOOKUP(FE20,$AE$7:$AJ$396,2) -> 1 | FG20: =IF(FD20<>FF20,1,0) -> 1 | FI20: 141 | FJ20: =VLOOKUP(FI20,$AE$7:$AJ$396,2) -> 2 | FO20: 156 | FP20: =VLOOKUP(FO20,$AE$7:$AJ$396,2) -> 1 | FQ20: Y | FR20: =IF(OR(AND(FP20=1,FQ20<>"Y"),AND(FP20=2,FQ20="Y")),1,0) -> 0 | FS20: 184 | FT20: =VLOOKUP(FS20,$AE$7:$AJ$396,2) -> 1 | FV20: =IF(OR(AND(FT20=1,FU20<>"Y"),AND(FT20=2,FU20="Y")),1,0) -> 1 | FX20: 376 | FY20: =VLOOKUP(FX20,$AE$7:$AJ$396,5) -> 0
B21: Line Length Errors: | C21: =IF(LEN(C11)<>60,1,0)+IF(LEN(C12)<>60,1,0)+IF(LEN(C13)<>60,1,0)+IF(LEN(C14)<>60,1,0)+IF(LEN(C15)<>60,1,0)+IF(LEN(C16)<>60,1,0)+IF(LEN(C17)<>30,1,0) -> 0 | U21: Manipulativeness | V21: =AS37 -> 3 | W21: =AS38 -> 47 | Z21: Raw | AA21: T | AB21: Criteria | AC21: Dx? | AE21: 15 | AF21: =IF(ISERROR(VALUE(MID($C$11,$AE21,1)))=TRUE,"TEXT",VALUE(MID($C$11,$AE21,1))) -> 2 | AH21: =IF(AF21=9,0,(IF(AG21="Y",AF21-1,2-AF21))) -> 0 | AI21: =IF(AF21=1,1,0) -> 0 | AJ21: =IF(AF21=2,1,0) -> 1 | AL21: 281 | AM21: =VLOOKUP(AL21,$AE$7:$AH$396,4) -> 0 | AO21: 163 | AP21: =VLOOKUP(AO21,$AE$7:$AH$396,4) -> 0 | AR21: 149 | AS21: =VLOOKUP(AR21,$AE$7:$AH$396,4) -> 1 | AU21: 148 | AV21: =VLOOKUP(AU21,$AE$7:$AH$396,4) -> 0 | AX21: 193 | AY21: =VLOOKUP(AX21,$AE$7:$AH$396,4) -> 0 | BG21: 213 | BH21: =VLOOKUP(BG21,$AE$7:$AH$396,4) -> 0 | BJ21: 123 | BK21: =VLOOKUP(BJ21,$AE$7:$AH$396,4) -> 0 | BM21: 283 | BN21: =VLOOKUP(BM21,$AE$7:$AH$396,4) -> 0 | BP21: 195 | BQ21: =VLOOKUP(BP21,$AE$7:$AH$396,4) -> 0 | BS21: 203 | BT21: =VLOOKUP(BS21,$AE$7:$AH$396,4) -> 0 | BV21: 177 | BW21: =VLOOKUP(BV21,$AE$7:$AH$396,4) -> 1 | BY21: 173 | BZ21: =VLOOKUP(BY21,$AE$7:$AH$396,4) -> 1 | CB21: 160 | CC21: =VLOOKUP(CB21,$AE$7:$AH$396,4) -> 0 | CE21: 192 | CF21: =VLOOKUP(CE21,$AE$7:$AH$396,4) -> 0 | CP21: 247 | CQ21: =VLOOKUP(CP21,$AE$7:$AJ$396,5) -> 0 | CR21: 307 | CS21: =VLOOKUP(CR21,$AE$7:$AJ$396,6) -> 1 | CU21: 191 | CV21: =VLOOKUP(CU21,$AE$7:$AJ$396,5) -> 1 | CZ21: 373 | DA21: =VLOOKUP(CZ21,$AE$7:$AJ$396,5) -> 0 | DE21: 178 | DF21: =VLOOKUP(DE21,$AE$7:$AJ$396,5) -> 1 | DJ21: 390 | DK21: =VLOOKUP(DJ21,$AE$7:$AJ$396,5) -> 0 | DO21: 311 | DP21: =VLOOKUP(DO21,$AE$7:$AJ$396,5) -> 0 | DT21: 336 | DU21: =VLOOKUP(DT21,$AE$7:$AJ$396,5) -> 0 | DY21: 171 | DZ21: =VLOOKUP(DY21,$AE$7:$AJ$396,5) -> 0 | ED21: 358 | EE21: =VLOOKUP(ED21,$AE$7:$AJ$396,5) -> 0 | EI21: 302 | EJ21: =VLOOKUP(EI21,$AE$7:$AJ$396,5) -> 0 | EN21: 205 | EO21: =VLOOKUP(EN21,$AE$7:$AJ$396,5) -> 0 | EX21: 178 | EY21: =VLOOKUP(EX21,$AE$7:$AJ$396,5) -> 1 | FC21: 89 | FD21: =VLOOKUP(FC21,$AE$7:$AJ$396,2) -> 1 | FE21: 173 | FF21: =VLOOKUP(FE21,$AE$7:$AJ$396,2) -> 2 | FG21: =IF(FD21<>FF21,1,0) -> 1 | FI21: 153 | FJ21: =VLOOKUP(FI21,$AE$7:$AJ$396,2) -> 1 | FO21: 176 | FP21: =VLOOKUP(FO21,$AE$7:$AJ$396,2) -> 2 | FR21: =IF(OR(AND(FP21=1,FQ21<>"Y"),AND(FP21=2,FQ21="Y")),1,0) -> 0 | FS21: 190 | FT21: =VLOOKUP(FS21,$AE$7:$AJ$396,2) -> 2 | FV21: =IF(OR(AND(FT21=1,FU21<>"Y"),AND(FT21=2,FU21="Y")),1,0) -> 0 | FX21: 381 | FY21: =VLOOKUP(FX21,$AE$7:$AJ$396,5) -> 0
B22: Missing Values: | C22: =COUNTIF(AF7:AF396,9) -> 0 | U22: Aggression | V22: =AV37 -> 6 | W22: =AV38 -> 58 | Y22: Diagnostic Scales | AE22: 16 | AF22: =IF(ISERROR(VALUE(MID($C$11,$AE22,1)))=TRUE,"TEXT",VALUE(MID($C$11,$AE22,1))) -> 2 | AG22: Y | AH22: =IF(AF22=9,0,(IF(AG22="Y",AF22-1,2-AF22))) -> 1 | AI22: =IF(AF22=1,1,0) -> 0 | AJ22: =IF(AF22=2,1,0) -> 1 | AL22: 288 | AM22: =VLOOKUP(AL22,$AE$7:$AH$396,4) -> 0 | AO22: 176 | AP22: =VLOOKUP(AO22,$AE$7:$AH$396,4) -> 0 | AR22: 159 | AS22: =VLOOKUP(AR22,$AE$7:$AH$396,4) -> 0 | AU22: 153 | AV22: =VLOOKUP(AU22,$AE$7:$AH$396,4) -> 0 | AX22: 206 | AY22: =VLOOKUP(AX22,$AE$7:$AH$396,4) -> 0 | BG22: 221 | BH22: =VLOOKUP(BG22,$AE$7:$AH$396,4) -> 0 | BJ22: 136 | BK22: =VLOOKUP(BJ22,$AE$7:$AH$396,4) -> 1 | BM22: 284 | BN22: =VLOOKUP(BM22,$AE$7:$AH$396,4) -> 0 | BP22: 217 | BQ22: =VLOOKUP(BP22,$AE$7:$AH$396,4) -> 0 | BS22: 215 | BT22: =VLOOKUP(BS22,$AE$7:$AH$396,4) -> 1 | BV22: 182 | BW22: =VLOOKUP(BV22,$AE$7:$AH$396,4) -> 0 | BY22: 185 | BZ22: =VLOOKUP(BY22,$AE$7:$AH$396,4) -> 1 | CB22: 184 | CC22: =VLOOKUP(CB22,$AE$7:$AH$396,4) -> 1 | CE22: 211 | CF22: =VLOOKUP(CE22,$AE$7:$AH$396,4) -> 0 | CP22: 261 | CQ22: =VLOOKUP(CP22,$AE$7:$AJ$396,5) -> 0 | CU22: 198 | CV22: =VLOOKUP(CU22,$AE$7:$AJ$396,5) -> 1 | CZ22: 376 | DA22: =VLOOKUP(CZ22,$AE$7:$AJ$396,5) -> 0 | DE22: 194 | DF22: =VLOOKUP(DE22,$AE$7:$AJ$396,5) -> 0 | DO22: 316 | DP22: =VLOOKUP(DO22,$AE$7:$AJ$396,5) -> 0 | DT22: 348 | DU22: =VLOOKUP(DT22,$AE$7:$AJ$396,5) -> 0 | DY22: 235 | DZ22: =VLOOKUP(DY22,$AE$7:$AJ$396,5) -> 0 | ED22: 371 | EE22: =VLOOKUP(ED22,$AE$7:$AJ$396,5) -> 0 | EI22: 310 | EJ22: =VLOOKUP(EI22,$AE$7:$AJ$396,5) -> 0 | EN22: 207 | EO22: =VLOOKUP(EN22,$AE$7:$AJ$396,5) -> 0 | EX22: 213 | EY22: =VLOOKUP(EX22,$AE$7:$AJ$396,5) -> 0 | FC22: 98 | FD22: =VLOOKUP(FC22,$AE$7:$AJ$396,2) -> 2 | FE22: 193 | FF22: =VLOOKUP(FE22,$AE$7:$AJ$396,2) -> 2 | FG22: =IF(FD22<>FF22,1,0) -> 0 | FI22: 98 | FJ22: =VLOOKUP(FI22,$AE$7:$AJ$396,2) -> 2 | FO22: 181 | FP22: =VLOOKUP(FO22,$AE$7:$AJ$396,2) -> 1 | FQ22: Y | FR22: =IF(OR(AND(FP22=1,FQ22<>"Y"),AND(FP22=2,FQ22="Y")),1,0) -> 0 | FS22: 203 | FT22: =VLOOKUP(FS22,$AE$7:$AJ$396,2) -> 2 | FV22: =IF(OR(AND(FT22=1,FU22<>"Y"),AND(FT22=2,FU22="Y")),1,0) -> 0 | FX22: 386 | FY22: =VLOOKUP(FX22,$AE$7:$AJ$396,5) -> 0
U23: Self-harm | V23: =AY37 -> 6 | W23: =AY38 -> 66 | Y23: Paranoid | Z23: =EP38 -> 4 | AA23: =EP39 -> 46 | AB23: =EP40 -> 0 | AC23: =EP41 -> N | AE23: 17 | AF23: =IF(ISERROR(VALUE(MID($C$11,$AE23,1)))=TRUE,"TEXT",VALUE(MID($C$11,$AE23,1))) -> 2 | AG23: Y | AH23: =IF(AF23=9,0,(IF(AG23="Y",AF23-1,2-AF23))) -> 1 | AI23: =IF(AF23=1,1,0) -> 0 | AJ23: =IF(AF23=2,1,0) -> 1 | AL23: 290 | AM23: =VLOOKUP(AL23,$AE$7:$AH$396,4) -> 0 | AO23: 188 | AP23: =VLOOKUP(AO23,$AE$7:$AH$396,4) -> 0 | AR23: 166 | AS23: =VLOOKUP(AR23,$AE$7:$AH$396,4) -> 0 | AU23: 165 | AV23: =VLOOKUP(AU23,$AE$7:$AH$396,4) -> 1 | AX23: 237 | AY23: =VLOOKUP(AX23,$AE$7:$AH$396,4) -> 1 | BJ23: 156 | BK23: =VLOOKUP(BJ23,$AE$7:$AH$396,4) -> 0 | BM23: 291 | BN23: =VLOOKUP(BM23,$AE$7:$AH$396,4) -> 0 | BP23: 223 | BQ23: =VLOOKUP(BP23,$AE$7:$AH$396,4) -> 0 | BS23: 226 | BT23: =VLOOKUP(BS23,$AE$7:$AH$396,4) -> 1 | BV23: 196 | BW23: =VLOOKUP(BV23,$AE$7:$AH$396,4) -> 0 | BY23: 189 | BZ23: =VLOOKUP(BY23,$AE$7:$AH$396,4) -> 0 | CB23: 201 | CC23: =VLOOKUP(CB23,$AE$7:$AH$396,4) -> 1 | CE23: 214 | CF23: =VLOOKUP(CE23,$AE$7:$AH$396,4) -> 0 | CP23: 268 | CQ23: =VLOOKUP(CP23,$AE$7:$AJ$396,5) -> 0 | CU23: 209 | CV23: =VLOOKUP(CU23,$AE$7:$AJ$396,5) -> 0 | CZ23: 385 | DA23: =VLOOKUP(CZ23,$AE$7:$AJ$396,5) -> 0 | DE23: 204 | DF23: =VLOOKUP(DE23,$AE$7:$AJ$396,5) -> 0 | DO23: 320 | DP23: =VLOOKUP(DO23,$AE$7:$AJ$396,5) -> 0 | DT23: 363 | DU23: =VLOOKUP(DT23,$AE$7:$AJ$396,5) -> 1 | DY23: 266 | DZ23: =VLOOKUP(DY23,$AE$7:$AJ$396,5) -> 0 | ED23: 372 | EE23: =VLOOKUP(ED23,$AE$7:$AJ$396,5) -> 0 | EI23: 352 | EJ23: =VLOOKUP(EI23,$AE$7:$AJ$396,5) -> 0 | EN23: 224 | EO23: =VLOOKUP(EN23,$AE$7:$AJ$396,5) -> 0 | EX23: 233 | EY23: =VLOOKUP(EX23,$AE$7:$AJ$396,5) -> 0 | FC23: 35 | FD23: =VLOOKUP(FC23,$AE$7:$AJ$396,2) -> 2 | FE23: 140 | FF23: =VLOOKUP(FE23,$AE$7:$AJ$396,2) -> 2 | FG23: =IF(FD23<>FF23,1,0) -> 0 | FI23: 161 | FJ23: =VLOOKUP(FI23,$AE$7:$AJ$396,2) -> 2 | FO23: 206 | FP23: =VLOOKUP(FO23,$AE$7:$AJ$396,2) -> 1 | FQ23: Y | FR23: =IF(OR(AND(FP23=1,FQ23<>"Y"),AND(FP23=2,FQ23="Y")),1,0) -> 0 | FS23: 205 | FT23: =VLOOKUP(FS23,$AE$7:$AJ$396,2) -> 2 | FV23: =IF(OR(AND(FT23=1,FU23<>"Y"),AND(FT23=2,FU23="Y")),1,0) -> 0 | FX23: 387 | FY23: =VLOOKUP(FX23,$AE$7:$AJ$396,5) -> 0
C24: =IF(OR($Z$16>0,$Z$17>0),"D A T A E N T R Y","") | U24: Low Self-esteem | V24: =BB37 -> 3 | W24: =BB38 -> 65 | Y24: Schizoid | Z24: =EU38 -> 7 | AA24: =EU39 -> 55 | AB24: =EU40 -> 0 | AC24: =EU41 -> N | AE24: 18 | AF24: =IF(ISERROR(VALUE(MID($C$11,$AE24,1)))=TRUE,"TEXT",VALUE(MID($C$11,$AE24,1))) -> 1 | AH24: =IF(AF24=9,0,(IF(AG24="Y",AF24-1,2-AF24))) -> 1 | AI24: =IF(AF24=1,1,0) -> 1 | AJ24: =IF(AF24=2,1,0) -> 0 | AL24: 294 | AM24: =VLOOKUP(AL24,$AE$7:$AH$396,4) -> 0 | AO24: 205 | AP24: =VLOOKUP(AO24,$AE$7:$AH$396,4) -> 0 | AR24: 186 | AS24: =VLOOKUP(AR24,$AE$7:$AH$396,4) -> 1 | AU24: 181 | AV24: =VLOOKUP(AU24,$AE$7:$AH$396,4) -> 0 | BJ24: 197 | BK24: =VLOOKUP(BJ24,$AE$7:$AH$396,4) -> 0 | BM24: 297 | BN24: =VLOOKUP(BM24,$AE$7:$AH$396,4) -> 0 | BV24: 207 | BW24: =VLOOKUP(BV24,$AE$7:$AH$396,4) -> 0 | BY24: 198 | BZ24: =VLOOKUP(BY24,$AE$7:$AH$396,4) -> 1 | CB24: 202 | CC24: =VLOOKUP(CB24,$AE$7:$AH$396,4) -> 1 | CE24: 227 | CF24: =VLOOKUP(CE24,$AE$7:$AH$396,4) -> 1 | CP24: 272 | CQ24: =VLOOKUP(CP24,$AE$7:$AJ$396,5) -> 0 | CU24: 228 | CV24: =VLOOKUP(CU24,$AE$7:$AJ$396,5) -> 0 | CZ24: 388 | DA24: =VLOOKUP(CZ24,$AE$7:$AJ$396,5) -> 0 | DE24: 205 | DF24: =VLOOKUP(DE24,$AE$7:$AJ$396,5) -> 0 | DO24: 325 | DP24: =VLOOKUP(DO24,$AE$7:$AJ$396,5) -> 0 | DT24: 374 | DU24: =VLOOKUP(DT24,$AE$7:$AJ$396,5) -> 0 | DY24: 321 | DZ24: =VLOOKUP(DY24,$AE$7:$AJ$396,5) -> 0 | ED24: 375 | EE24: =VLOOKUP(ED24,$AE$7:$AJ$396,5) -> 0 | EI24: 356 | EJ24: =VLOOKUP(EI24,$AE$7:$AJ$396,5) -> 0 | EN24: 275 | EO24: =VLOOKUP(EN24,$AE$7:$AJ$396,5) -> 0 | EX24: 285 | EY24: =VLOOKUP(EX24,$AE$7:$AJ$396,5) -> 0 | FC24: 54 | FD24: =VLOOKUP(FC24,$AE$7:$AJ$396,2) -> 2 | FE24: 116 | FF24: =VLOOKUP(FE24,$AE$7:$AJ$396,2) -> 2 | FG24: =IF(FD24<>FF24,1,0) -> 0 | FI24: 190 | FJ24: =VLOOKUP(FI24,$AE$7:$AJ$396,2) -> 2 | FO24: 225 | FP24: =VLOOKUP(FO24,$AE$7:$AJ$396,2) -> 2 | FQ24: Y | FR24: =IF(OR(AND(FP24=1,FQ24<>"Y"),AND(FP24=2,FQ24="Y")),1,0) -> 1 | FS24: 212 | FT24: =VLOOKUP(FS24,$AE$7:$AJ$396,2) -> 2 | FV24: =IF(OR(AND(FT24=1,FU24<>"Y"),AND(FT24=2,FU24="Y")),1,0) -> 0 | FX24: 390 | FY24: =VLOOKUP(FX24,$AE$7:$AJ$396,5) -> 0
C25: =IF(OR($Z$16>0,$Z$17>0),"E R R O R !","") | U25: Suicide Proneness | V25: =BE37 -> 3 | W25: =BE38 -> 63 | Y25: Schizotypal | Z25: =EZ38 -> 5 | AA25: =EZ39 -> 46 | AB25: =EZ40 -> 0 | AC25: =EZ41 -> N | AE25: 19 | AF25: =IF(ISERROR(VALUE(MID($C$11,$AE25,1)))=TRUE,"TEXT",VALUE(MID($C$11,$AE25,1))) -> 2 | AG25: Y | AH25: =IF(AF25=9,0,(IF(AG25="Y",AF25-1,2-AF25))) -> 1 | AI25: =IF(AF25=1,1,0) -> 0 | AJ25: =IF(AF25=2,1,0) -> 1 | AL25: 298 | AM25: =VLOOKUP(AL25,$AE$7:$AH$396,4) -> 1 | AO25: 216 | AP25: =VLOOKUP(AO25,$AE$7:$AH$396,4) -> 0 | AR25: 200 | AS25: =VLOOKUP(AR25,$AE$7:$AH$396,4) -> 0 | AU25: 194 | AV25: =VLOOKUP(AU25,$AE$7:$AH$396,4) -> 0 | BJ25: 230 | BK25: =VLOOKUP(BJ25,$AE$7:$AH$396,4) -> 0 | BM25: 300 | BN25: =VLOOKUP(BM25,$AE$7:$AH$396,4) -> 1 | BV25: 218 | BW25: =VLOOKUP(BV25,$AE$7:$AH$396,4) -> 1 | BY25: 228 | BZ25: =VLOOKUP(BY25,$AE$7:$AH$396,4) -> 0 | CB25: 210 | CC25: =VLOOKUP(CB25,$AE$7:$AH$396,4) -> 0 | CE25: 234 | CF25: =VLOOKUP(CE25,$AE$7:$AH$396,4) -> 0 | CP25: 282 | CQ25: =VLOOKUP(CP25,$AE$7:$AJ$396,5) -> 0 | CU25: 229 | CV25: =VLOOKUP(CU25,$AE$7:$AJ$396,5) -> 0 | DE25: 232 | DF25: =VLOOKUP(DE25,$AE$7:$AJ$396,5) -> 0 | DO25: 358 | DP25: =VLOOKUP(DO25,$AE$7:$AJ$396,5) -> 0 | DT25: 384 | DU25: =VLOOKUP(DT25,$AE$7:$AJ$396,5) -> 0 | DY25: 332 | DZ25: =VLOOKUP(DY25,$AE$7:$AJ$396,5) -> 0 | ED25: 378 | EE25: =VLOOKUP(ED25,$AE$7:$AJ$396,5) -> 0 | EI25: 365 | EJ25: =VLOOKUP(EI25,$AE$7:$AJ$396,5) -> 0 | EN25: 299 | EO25: =VLOOKUP(EN25,$AE$7:$AJ$396,5) -> 0 | EX25: 299 | EY25: =VLOOKUP(EX25,$AE$7:$AJ$396,5) -> 0 | FC25: 111 | FD25: =VLOOKUP(FC25,$AE$7:$AJ$396,2) -> 2 | FE25: 168 | FF25: =VLOOKUP(FE25,$AE$7:$AJ$396,2) -> 1 | FG25: =IF(FD25<>FF25,1,0) -> 1 | FI25: 206 | FJ25: =VLOOKUP(FI25,$AE$7:$AJ$396,2) -> 1
U26: Eccentric Perceptions | V26: =BH37 -> 2 | W26: =BH38 -> 44 | AE26: 20 | AF26: =IF(ISERROR(VALUE(MID($C$11,$AE26,1)))=TRUE,"TEXT",VALUE(MID($C$11,$AE26,1))) -> 2 | AH26: =IF(AF26=9,0,(IF(AG26="Y",AF26-1,2-AF26))) -> 0 | AI26: =IF(AF26=1,1,0) -> 0 | AJ26: =IF(AF26=2,1,0) -> 1 | AL26: 301 | AM26: =VLOOKUP(AL26,$AE$7:$AH$396,4) -> 0 | AO26: 224 | AP26: =VLOOKUP(AO26,$AE$7:$AH$396,4) -> 0 | AR26: 208 | AS26: =VLOOKUP(AR26,$AE$7:$AH$396,4) -> 0 | AU26: 212 | AV26: =VLOOKUP(AU26,$AE$7:$AH$396,4) -> 0 | BM26: 306 | BN26: =VLOOKUP(BM26,$AE$7:$AH$396,4) -> 1 | BY26: 236 | BZ26: =VLOOKUP(BY26,$AE$7:$AH$396,4) -> 1 | CB26: 222 | CC26: =VLOOKUP(CB26,$AE$7:$AH$396,4) -> 0 | CP26: 318 | CQ26: =VLOOKUP(CP26,$AE$7:$AJ$396,5) -> 0 | CU26: 232 | CV26: =VLOOKUP(CU26,$AE$7:$AJ$396,5) -> 0 | DE26: 245 | DF26: =VLOOKUP(DE26,$AE$7:$AJ$396,5) -> 0 | DO26: 377 | DP26: =VLOOKUP(DO26,$AE$7:$AJ$396,5) -> 0 | DY26: 334 | DZ26: =VLOOKUP(DY26,$AE$7:$AJ$396,5) -> 0 | ED26: 382 | EE26: =VLOOKUP(ED26,$AE$7:$AJ$396,5) -> 0 | EI26: 366 | EJ26: =VLOOKUP(EI26,$AE$7:$AJ$396,5) -> 0 | EN26: 335 | EO26: =VLOOKUP(EN26,$AE$7:$AJ$396,5) -> 0 | EX26: 333 | EY26: =VLOOKUP(EX26,$AE$7:$AJ$396,5) -> 0 | FC26: 244 | FD26: =VLOOKUP(FC26,$AE$7:$AJ$396,2) -> 2 | FE26: 259 | FF26: =VLOOKUP(FE26,$AE$7:$AJ$396,2) -> 2 | FG26: =IF(FD26<>FF26,1,0) -> 0 | FI26: 6 | FJ26: =VLOOKUP(FI26,$AE$7:$AJ$396,2) -> 1
U27: Dependency | V27: =BK37 -> 5 | W27: =BK38 -> 53 | Y27: Antisocial | Z27: =CW35 -> 6 | AA27: =CW36 -> 48 | AB27: =CW37 -> 0/2 | AC27: =CW38 -> N | AE27: 21 | AF27: =IF(ISERROR(VALUE(MID($C$11,$AE27,1)))=TRUE,"TEXT",VALUE(MID($C$11,$AE27,1))) -> 2 | AH27: =IF(AF27=9,0,(IF(AG27="Y",AF27-1,2-AF27))) -> 0 | AI27: =IF(AF27=1,1,0) -> 0 | AJ27: =IF(AF27=2,1,0) -> 1 | AL27: 309 | AM27: =VLOOKUP(AL27,$AE$7:$AH$396,4) -> 0 | AR27: 219 | AS27: =VLOOKUP(AR27,$AE$7:$AH$396,4) -> 0 | AU27: 225 | AV27: =VLOOKUP(AU27,$AE$7:$AH$396,4) -> 1 | BM27: 308 | BN27: =VLOOKUP(BM27,$AE$7:$AH$396,4) -> 1 | CB27: 231 | CC27: =VLOOKUP(CB27,$AE$7:$AH$396,4) -> 0 | CP27: 326 | CQ27: =VLOOKUP(CP27,$AE$7:$AJ$396,5) -> 1 | CU27: 243 | CV27: =VLOOKUP(CU27,$AE$7:$AJ$396,5) -> 0 | DE27: 252 | DF27: =VLOOKUP(DE27,$AE$7:$AJ$396,5) -> 0 | DO27: 381 | DP27: =VLOOKUP(DO27,$AE$7:$AJ$396,5) -> 0 | DY27: 349 | DZ27: =VLOOKUP(DY27,$AE$7:$AJ$396,5) -> 0 | EI27: 367 | EJ27: =VLOOKUP(EI27,$AE$7:$AJ$396,5) -> 0 | EN27: 360 | EO27: =VLOOKUP(EN27,$AE$7:$AJ$396,5) -> 0 | EX27: 342 | EY27: =VLOOKUP(EX27,$AE$7:$AJ$396,5) -> 1 | FC27: 242 | FD27: =VLOOKUP(FC27,$AE$7:$AJ$396,2) -> 1 | FE27: 270 | FF27: =VLOOKUP(FE27,$AE$7:$AJ$396,2) -> 2 | FG27: =IF(FD27<>FF27,1,0) -> 1 | FI27: 69 | FJ27: =VLOOKUP(FI27,$AE$7:$AJ$396,2) -> 2
Y28: Borderline | Z28: =DG38 -> 8 | AA28: =DG39 -> 53 | AB28: =DG40 -> 0 | AC28: =DG41 -> N | AE28: 22 | AF28: =IF(ISERROR(VALUE(MID($C$11,$AE28,1)))=TRUE,"TEXT",VALUE(MID($C$11,$AE28,1))) -> 2 | AH28: =IF(AF28=9,0,(IF(AG28="Y",AF28-1,2-AF28))) -> 0 | AI28: =IF(AF28=1,1,0) -> 0 | AJ28: =IF(AF28=2,1,0) -> 1 | AL28: 311 | AM28: =VLOOKUP(AL28,$AE$7:$AH$396,4) -> 0 | BM28: 317 | BN28: =VLOOKUP(BM28,$AE$7:$AH$396,4) -> 1 | CP28: 329 | CQ28: =VLOOKUP(CP28,$AE$7:$AJ$396,5) -> 0 | CU28: 258 | CV28: =VLOOKUP(CU28,$AE$7:$AJ$396,5) -> 0 | DA28: raw score: | DB28: =SUM(DA8:DA27,DC8:DC27) -> 3 | DE28: 269 | DF28: =VLOOKUP(DE28,$AE$7:$AJ$396,5) -> 0 | DY28: 371 | DZ28: =VLOOKUP(DY28,$AE$7:$AJ$396,5) -> 0 | EX28: 344 | EY28: =VLOOKUP(EX28,$AE$7:$AJ$396,5) -> 1 | FC28: 249 | FD28: =VLOOKUP(FC28,$AE$7:$AJ$396,2) -> 1 | FE28: 262 | FF28: =VLOOKUP(FE28,$AE$7:$AJ$396,2) -> 2 | FG28: =IF(FD28<>FF28,1,0) -> 1 | FI28: 45 | FJ28: =VLOOKUP(FI28,$AE$7:$AJ$396,2) -> 2 | FR28: hi raw | FS28: =SUM(FR8:FR24) -> 4
U29: Positive Temperament | V29: =BN37 -> 13 | W29: =BN38 -> 40 | Y29: Histrionic | Z29: =DV38 -> 5 | AA29: =DV39 -> 41 | AB29: =DV40 -> 0 | AC29: =DV41 -> N | AE29: 23 | AF29: =IF(ISERROR(VALUE(MID($C$11,$AE29,1)))=TRUE,"TEXT",VALUE(MID($C$11,$AE29,1))) -> 2 | AH29: =IF(AF29=9,0,(IF(AG29="Y",AF29-1,2-AF29))) -> 0 | AI29: =IF(AF29=1,1,0) -> 0 | AJ29: =IF(AF29=2,1,0) -> 1 | AL29: 312 | AM29: =VLOOKUP(AL29,$AE$7:$AH$396,4) -> 0 | BM29: 319 | BN29: =VLOOKUP(BM29,$AE$7:$AH$396,4) -> 1 | CU29: 289 | CV29: =VLOOKUP(CU29,$AE$7:$AJ$396,5) -> 0 | DA29: T score: | DB29: =(((DB28-5.22)/4.03)*10)+50 -> 44 | DE29: 273 | DF29: =VLOOKUP(DE29,$AE$7:$AJ$396,5) -> 0 | EX29: 384 | EY29: =VLOOKUP(EX29,$AE$7:$AJ$396,5) -> 0 | FC29: 248 | FD29: =VLOOKUP(FC29,$AE$7:$AJ$396,2) -> 2 | FE29: 269 | FF29: =VLOOKUP(FE29,$AE$7:$AJ$396,2) -> 2 | FG29: =IF(FD29<>FF29,1,0) -> 0 | FI29: 183 | FJ29: =VLOOKUP(FI29,$AE$7:$AJ$396,2) -> 2 | FR29: lo raw | FS29: =SUM(FV8:FV24) -> 4
U30: Exhibitionism | V30: =BQ37 -> 6 | W30: =BQ38 -> 48 | Y30: Narcissistic | Z30: =EA38 -> 6 | AA30: =EA39 -> 41 | AB30: =EA40 -> 0 | AC30: =EA41 -> N | AE30: 24 | AF30: =IF(ISERROR(VALUE(MID($C$11,$AE30,1)))=TRUE,"TEXT",VALUE(MID($C$11,$AE30,1))) -> 2 | AG30: Y | AH30: =IF(AF30=9,0,(IF(AG30="Y",AF30-1,2-AF30))) -> 1 | AI30: =IF(AF30=1,1,0) -> 0 | AJ30: =IF(AF30=2,1,0) -> 1 | AL30: 316 | AM30: =VLOOKUP(AL30,$AE$7:$AH$396,4) -> 0 | BM30: 324 | BN30: =VLOOKUP(BM30,$AE$7:$AH$396,4) -> 1 | CU30: 318 | CV30: =VLOOKUP(CU30,$AE$7:$AJ$396,5) -> 0 | DA30: criteria: | DB30: =SUM(DB33:DB39) -> 0 | DE30: 274 | DF30: =VLOOKUP(DE30,$AE$7:$AJ$396,5) -> 0 | FI30: 57 | FJ30: =VLOOKUP(FI30,$AE$7:$AJ$396,2) -> 2 | FR30: DRIN raw | FS30: =FS28+(17-FS29) -> 17
